Workbook

Sheet 成績一覧
C1: =投入確認!A1 -> 3月31日まで | I1: 百貨店 和惣菜
A2: 売上順 | C2: 本年 | D2: 前年 | E2: 昨対比 | F2: 昨対順 | G2: 上代達成率 | H2: 上代累計
A3: =投入確認!B22 -> 1 | B3: =投入確認!F22 -> 名古屋 | C3: =投入確認!E22 -> 11702447 | D3: =投入確認!D22 -> 9780171 | E3: =投入確認!C22 -> 1.1965483 | F3: =投入確認!A22 -> 2 | H3: =名古屋!E35 -> 0
A4: =投入確認!B14 -> 2 | B4: =投入確認!F14 -> 泉北 | C4: =投入確認!E14 -> 11647246 | D4: =投入確認!D14 -> 10866553 | E4: =投入確認!C14 -> 1.0718437 | F4: =投入確認!A14 -> 5 | G4: =C4/H4 -> 0.82132089 | H4: =泉北!E35 -> 14181115 | I4: 1.07
A5: =投入確認!B12 -> 3 | B5: =投入確認!F12 -> なんば | C5: =投入確認!E12 -> 10974132 | D5: =投入確認!D12 -> 11260157 | E5: =投入確認!C12 -> 0.97459849 | F5: =投入確認!A12 -> 19 | G5: 107.9 | H5: =なんば!E34 -> 0
A6: =投入確認!B3 -> 4 | B6: =投入確認!F3 -> あべの | C6: =投入確認!E3 -> 10124333 | D6: =投入確認!D3 -> 10505917 | E6: =投入確認!C3 -> 0.96367913 | F6: =投入確認!A3 -> 20 | H6: =あべの!E35 -> 0
A7: =投入確認!B30 -> 5 | B7: =投入確認!F30 -> 東京 | C7: =投入確認!E30 -> 10028367 | D7: =投入確認!D30 -> 10267776 | E7: =投入確認!C30 -> 0.97668346 | F7: =投入確認!A30 -> 18 | H7: =東京!E35 -> 0 | I7: 106.2
A8: =投入確認!B16 -> 6 | B8: =投入確認!F16 -> うめ阪 | C8: =投入確認!E16 -> 9794453 | D8: =投入確認!D16 -> 9809268 | E8: =投入確認!C16 -> 0.99848969 | F8: =投入確認!A16 -> 15 | G8: =C8/H8 -> 0.87988808 | H8: =うめ阪!E35 -> 11131476 | I8: 0.983
A9: =投入確認!B44 -> 7 | B9: =投入確認!F44 -> 伊勢丹 | C9: =投入確認!E44 -> 8967638 | D9: =投入確認!D44 -> 9935383 | E9: =投入確認!C44 -> 0.90259611 | F9: =投入確認!A44 -> 30 | G9: 104,3 | H9: =伊勢丹!E35 -> 0
A10: =投入確認!B4 -> 8 | B10: =投入確認!F4 -> 上本町 | C10: =投入確認!E4 -> 8713399 | D10: =投入確認!D4 -> 8893470 | E10: =投入確認!C4 -> 0.97975245 | F10: =投入確認!A4 -> 16 | H10: =上本町!E35 -> 0
A11: =投入確認!B33 -> 9 | B11: =投入確認!F33 -> 横浜 | C11: =投入確認!E33 -> 8348850 | D11: =投入確認!D33 -> 8074824 | E11: =投入確認!C33 -> 1.0339358 | F11: =投入確認!A33 -> 10 | G11: =C11/H11 -> 0.96223209 | H11: =横浜!E35 -> 8676545
A12: =投入確認!B32 -> 10 | B12: =投入確認!F32 -> 西宮 | C12: =投入確認!E32 -> 7221376 | D12: =投入確認!D32 -> 7018121 | E12: =投入確認!C32 -> 1.0289615 | F12: =投入確認!A32 -> 11 | H12: =西宮!E35 -> 8112147 | I12: 1.022
A13: =投入確認!B18 -> 11 | B13: =投入確認!F18 -> 神戸阪 | C13: =投入確認!E18 -> 7187481 | D13: =投入確認!D18 -> 7787354 | E13: =投入確認!C18 -> 0.92296832 | F13: =投入確認!A18 -> 27 | G13: =C13/H13 -> 0.875088 | H13: =神戸阪!E35 -> 8213438 | I13: 0.98
A14: =投入確認!B31 -> 12 | B14: 池東武 | C14: =投入確認!E31 -> 6452065 | D14: =投入確認!D31 -> 9858822 | E14: =投入確認!C31 -> 0.65444584 | F14: =投入確認!A31 -> 37 | G14: =C14/H14 -> #DIV/0! | H14: =池東武!E35 -> 0 | I14: 0.871
A15: =投入確認!B7 -> 13 | B15: =投入確認!F7 -> 京都 | C15: =投入確認!E7 -> 5920879 | D15: =投入確認!D7 -> 5854628 | E15: =投入確認!C7 -> 1.011316 | F15: =投入確認!A7 -> 13 | H15: =京都!E35 -> 0
A16: =投入確認!B41 -> 14 | B16: =投入確認!F41 -> 梅阪神 | C16: =投入確認!E41 -> 5724446 | D16: =投入確認!D41 -> 5997043 | E16: =投入確認!C41 -> 0.95454476 | F16: =投入確認!A41 -> 22 | G16: =C16/H16 -> 0.87055741 | H16: =梅阪神!E35 -> 6575610 | I16: 1.003
A17: =投入確認!B17 -> 15 | B17: =投入確認!F17 -> 宝塚 | C17: =投入確認!E17 -> 5230981 | D17: =投入確認!D17 -> 5538053 | E17: =投入確認!C17 -> 0.94455235 | F17: =投入確認!A17 -> 25 | G17: =C17/H17 -> 0.93930937 | H17: =宝塚!E35 -> 5568965
A18: =投入確認!B10 -> 16 | B18: =投入確認!F10 -> 守口 | C18: =投入確認!E10 -> 5109744 | D18: =投入確認!D10 -> 4824904 | E18: =投入確認!C10 -> 1.0590354 | F18: =投入確認!A10 -> 7 | G18: =C18/H18 -> 0.86693244 | H18: =守口!E35 -> 5894051
A19: =投入確認!B40 -> 17 | B19: =投入確認!F40 -> はか阪 | C19: =投入確認!E40 -> 4975237 | D19: =投入確認!D40 -> 5681423 | E19: =投入確認!C40 -> 0.87570262 | F19: =投入確認!A40 -> 32 | G19: 91,6% | H19: =はか阪!E35 -> 0 | I19: 94,7%
A20: =投入確認!B21 -> 18 | B20: =投入確認!F21 -> 川西 | C20: =投入確認!E21 -> 4937018 | D20: =投入確認!D21 -> 4803368 | E20: =投入確認!C21 -> 1.0278242 | F20: =投入確認!A21 -> 12 | H20: =川西!E35 -> 6037173 | I20: =C20/H20 -> 0.81776984
A21: =投入確認!B38 -> 20 | B21: =投入確認!F38 -> 栄 | C21: =投入確認!E38 -> 4650692 | D21: =投入確認!D38 -> 5103916 | E21: =投入確認!C38 -> 0.91120073 | F21: =投入確認!A38 -> 29 | G21: =C21/H21 -> 0.86420813 | H21: =栄!E35 -> 5381449
A22: =投入確認!B20 -> 19 | B22: =投入確認!F20 -> 京橋 | C22: =投入確認!E20 -> 4724505 | D22: =投入確認!D20 -> 5619405 | E22: =投入確認!C20 -> 0.84074826 | F22: =投入確認!A20 -> 34 | G22: =C22/H22 -> 0.81350792 | H22: =京橋!E35 -> 5807571 | I22: 0.985
A23: =投入確認!B39 -> 21 | B23: =投入確認!F39 -> 上野 | C23: =投入確認!E39 -> 4590502 | D23: =投入確認!D39 -> 4273477 | E23: =投入確認!C39 -> 1.0741843 | F23: =投入確認!A39 -> 4 | G23: =C23/H23 -> #DIV/0! | H23: =上野!E35 -> 0 | I23: 1.029
A24: =投入確認!B15 -> 22 | B24: =投入確認!F15 -> 岡山 | C24: =投入確認!E15 -> 4566455 | D24: =投入確認!D15 -> 4668031 | E24: =投入確認!C15 -> 0.97824008 | F24: =投入確認!A15 -> 17 | G24: =C24/H24 -> #DIV/0! | H24: =岡山!E35 -> 0 | I24: 98.9
A25: =投入確認!B19 -> 23 | B25: =投入確認!F19 -> 千里 | C25: =投入確認!E19 -> 4281266 | D25: =投入確認!D19 -> 4619838 | E25: =投入確認!C19 -> 0.92671345 | F25: =投入確認!A19 -> 26 | G25: =C25/H25 -> 0.88736069 | H25: =千里!E35 -> 4824719
A26: =投入確認!B27 -> 24 | B26: =投入確認!F27 -> 新宿 | C26: =投入確認!E27 -> 4184830 | D26: =投入確認!D27 -> 3308324 | E26: =投入確認!C27 -> 1.2649396 | F26: =投入確認!A27 -> 1 | G26: =C26/H26 -> 0.94128737 | H26: =新宿!E35 -> 4445858 | I26: 1.051
A27: =投入確認!B36 -> 25 | B27: =投入確認!F36 -> 柏 | C27: =投入確認!E36 -> 3935008 | D27: =投入確認!D36 -> 3478022 | E27: =投入確認!C36 -> 1.1313925 | F27: =投入確認!A36 -> 3 | H27: =柏!E35 -> 0
A28: =投入確認!B26 -> 26 | B28: =投入確認!F26 -> 流山 | C28: =投入確認!E26 -> 3794815 | D28: =投入確認!D26 -> 3569416 | E28: =投入確認!C26 -> 1.0631473 | F28: =投入確認!A26 -> 6 | H28: =流山!E35 -> 0 | I28: 1.06
A29: =投入確認!B9 -> 27 | B29: =投入確認!F9 -> 和歌山 | C29: =投入確認!E9 -> 3540021 | D29: =投入確認!D9 -> 3418708 | E29: =投入確認!C9 -> 1.035485 | F29: =投入確認!A9 -> 9 | G29: =C29/H29 -> 0.91499466 | H29: =和歌山!E35 -> 3868898
A30: =投入確認!B25 -> 28 | B30: 小倉 | C30: =投入確認!E25 -> 3405215 | D30: =投入確認!D25 -> 3595335 | E30: =投入確認!C25 -> 0.94712037 | F30: =投入確認!A25 -> 24 | G30: =C30/H30 -> #DIV/0! | H30: =小倉!E35 -> 0
A31: =投入確認!B35 -> 29 | B31: =投入確認!F35 -> 梅大丸 | C31: =投入確認!E35 -> 3370539 | D31: =投入確認!D35 -> 3345630 | E31: =投入確認!C35 -> 1.0074452 | F31: =投入確認!A35 -> 14 | G31: =C31/H31 -> 0.82606593 | H31: =梅大丸!E35 -> 4080230
A32: =投入確認!B11 -> 30 | B32: =投入確認!F11 -> 枚方 | C32: =投入確認!E11 -> 3234511 | D32: =投入確認!D11 -> 3401987 | E32: =投入確認!C11 -> 0.95077112 | F32: =投入確認!A11 -> 23 | G32: =C32/H32 -> 0.78848761 | H32: =枚方!E35 -> 4102171 | I32: 1.046
A33: =投入確認!B37 -> 31 | B33: =投入確認!F37 -> 神大丸 | C33: =投入確認!E37 -> 3203569 | D33: =投入確認!D37 -> 3354172 | E33: =投入確認!C37 -> 0.9550998 | F33: =投入確認!A37 -> 21 | G33: =C33/H33 -> #DIV/0! | H33: =神大丸!E35 -> 0 | I33: 0.971
A34: =投入確認!B29 -> 32 | B34: =投入確認!F29 -> 松山 | C34: =投入確認!E29 -> 3078755 | D34: =投入確認!D29 -> 2930310 | E34: =投入確認!C29 -> 1.0506585 | F34: =投入確認!A29 -> 8 | G34: =C34/H34 -> 1.5369867 | H34: =松山!E35 -> 2003111 | I34: 1.044
A35: =投入確認!B34 -> 34 | B35: =投入確認!F34 -> あまがさき | C35: =投入確認!E34 -> 2544877 | D35: =投入確認!D34 -> 2788089 | E35: =投入確認!C34 -> 0.91276749 | F35: =投入確認!A34 -> 28 | G35: =C35/H35 -> 0.851335 | H35: =あまが!E35 -> 2989278
A36: =投入確認!B6 -> 33 | B36: =投入確認!F6 -> 橿原 | C36: =投入確認!E6 -> 2553402 | D36: =投入確認!D6 -> 3292726 | E36: =投入確認!C6 -> 0.7754675 | F36: =投入確認!A6 -> 35 | G36: =C36/H36 -> 0.80309146 | H36: =橿原!E35 -> 3179466 | I36: 0.992
A37: =投入確認!B42 -> 35 | B37: =投入確認!F42 -> 高槻 | C37: =投入確認!E42 -> 2401225 | D37: =投入確認!D42 -> 2722345 | E37: =投入確認!C42 -> 0.88204287 | F37: =投入確認!A42 -> 31 | G37: =C37/H37 -> 0.80559043 | H37: =高槻!E35 -> 2980702
A38: =投入確認!B5 -> 36 | B38: =投入確認!F5 -> 東大阪 | C38: =投入確認!E5 -> 2217491 | D38: =投入確認!D5 -> 2587689 | E38: =投入確認!C5 -> 0.85693876 | F38: =投入確認!A5 -> 33 | H38: =東大阪!E35 -> 0
A39: =投入確認!B8 -> 37 | B39: =投入確認!F8 -> 洛西 | C39: =投入確認!E8 -> 1208400 | D39: =投入確認!D8 -> 1642879 | E39: =投入確認!C8 -> 0.73553804 | F39: =投入確認!A8 -> 36 | G39: =C39/H39 -> 0.81760517 | H39: =洛西!E35 -> 1477975
B40: =投入確認!F13 -> 堺 | C40: =投入確認!E13 -> 0 | D40: =投入確認!D13 -> 4632618 | E40: =投入確認!C13 -> 0 | H40: =堺!E35 -> 0
...

Sheet 投入確認
A1: 3月31日まで
A2: 昨対順位 | B2: 売上順位 | C2: 昨年対比 | D2: 前年 | E2: 本年 | F2: 46082 | G2: 1日 | H2: 2日 | I2: 3日 | J2: 4日 | K2: 5日 | L2: 6日 | M2: 7日 | N2: 8日 | O2: 9日 | P2: 10日 | Q2: 11日 | R2: 12日 | S2: 13日 | T2: 14日 | U2: 15日 | V2: 16日 | W2: 17日 | X2: 18日 | Y2: 19日 | Z2: 20日 | AA2: 21日 | AB2: 22日 | AC2: 23日 | AD2: 24日 | AE2: 25日 | AF2: 26日 | AG2: 27日 | AH2: 28日 | AI2: 29日 | AJ2: 30日 | AK2: 31日 | AL2: 合計 | AM2: 客数合計
A3: =RANK(C3,$C$3:$C$44,0) -> 20 | B3: =RANK(E3,$E$3:$E$44,0) -> 4 | C3: =IF(E3<1,0,E3/D3) -> 0.96367913 | D3: =SUM(G64:AK64) -> 10505917 | E3: =SUM(G3:AK3) -> 10124333 | F3: あべの | G3: =あべの!A4 -> 361304 | H3: =あべの!A5 -> 275126 | I3: =あべの!A6 -> 256960 | J3: =あべの!A7 -> 334728 | K3: =あべの!A8 -> 357944 | L3: =あべの!A9 -> 329125 | M3: =あべの!A10 -> 357388 | N3: =あべの!A11 -> 367947 | O3: =あべの!A12 -> 293445 | P3: =あべの!A13 -> 337266 | Q3: =あべの!A14 -> 352648 | R3: =あべの!A15 -> 339892 | S3: =あべの!A16 -> 365529 | T3: =あべの!A17 -> 356288 | U3: =あべの!A18 -> 362514 | V3: =あべの!A19 -> 292823 | W3: =あべの!A20 -> 335583 | X3: =あべの!A21 -> 289095 | Y3: =あべの!A22 -> 312811 | Z3: =あべの!A23 -> 389403 | AA3: =あべの!A24 -> 393835 | AB3: =あべの!A25 -> 344822 | AC3: =あべの!A26 -> 275631 | AD3: =あべの!A27 -> 317206 | AE3: =あべの!A28 -> 300010 | AF3: =あべの!A29 -> 335654 | AG3: =あべの!A30 -> 319071 | AH3: =あべの!A31 -> 340831 | AI3: =あべの!A32 -> 321714 | AJ3: =あべの!A33 -> 268227 | AK3: =あべの!A34 -> 239513 | AL3: =SUM(G3:AK3) -> 10124333 | AM3: =あべの!F35 -> 10743
A4: =RANK(C4,$C$3:$C$44,0) -> 16 | B4: =RANK(E4,$E$3:$E$44,0) -> 8 | C4: =IF(E4<1,0,E4/D4) -> 0.97975245 | D4: =SUM(G65:AK65) -> 8893470 | E4: =SUM(G4:AK4) -> 8713399 | F4: 上本町 | G4: =上本町!A4 -> 277402 | H4: =上本町!A5 -> 354333 | I4: =上本町!A6 -> 254413 | J4: =上本町!A7 -> 245540 | K4: =上本町!A8 -> 274631 | L4: =上本町!A9 -> 293487 | M4: =上本町!A10 -> 299267 | N4: =上本町!A11 -> 268903 | O4: =上本町!A12 -> 242197 | P4: =上本町!A13 -> 278134 | Q4: =上本町!A14 -> 398878 | R4: =上本町!A15 -> 266471 | S4: =上本町!A16 -> 254441 | T4: =上本町!A17 -> 306046 | U4: =上本町!A18 -> 275191 | V4: =上本町!A19 -> 227596 | W4: =上本町!A20 -> 237134 | X4: =上本町!A21 -> 248764 | Y4: =上本町!A22 -> 265312 | Z4: =上本町!A23 -> 289976 | AA4: =上本町!A24 -> 279182 | AB4: =上本町!A25 -> 257191 | AC4: =上本町!A26 -> 310007 | AD4: =上本町!A27 -> 263755 | AE4: =上本町!A28 -> 252910 | AF4: =上本町!A29 -> 384858 | AG4: =上本町!A30 -> 261252 | AH4: =上本町!A31 -> 279789 | AI4: =上本町!A32 -> 273213 | AJ4: =上本町!A33 -> 380433 | AK4: =上本町!A34 -> 212693 | AL4: =SUM(G4:AK4) -> 8713399 | AM4: =上本町!F35 -> 9367
A5: =RANK(C5,$C$3:$C$44,0) -> 33 | B5: =RANK(E5,$E$3:$E$44,0) -> 36 | C5: =IF(E5<1,0,E5/D5) -> 0.85693876 | D5: =SUM(G66:AK66) -> 2587689 | E5: =SUM(G5:AK5) -> 2217491 | F5: 東大阪 | G5: =東大阪!A4 -> 74661 | H5: =東大阪!A5 -> 64738 | I5: =東大阪!A6 -> 63793 | J5: =東大阪!A7 -> 74746 | K5: =東大阪!A8 -> 72019 | L5: =東大阪!A9 -> 69394 | M5: =東大阪!A10 -> 69827 | N5: =東大阪!A11 -> 78223 | O5: =東大阪!A12 -> 66080 | P5: =東大阪!A13 -> 69919 | Q5: =東大阪!A14 -> 70912 | R5: =東大阪!A15 -> 68500 | S5: =東大阪!A16 -> 72879 | T5: =東大阪!A17 -> 75599 | U5: =東大阪!A18 -> 80380 | V5: =東大阪!A19 -> 75433 | W5: =東大阪!A20 -> 72192 | X5: =東大阪!A21 -> 73014 | Y5: =東大阪!A22 -> 70079 | Z5: =東大阪!A23 -> 80251 | AA5: =東大阪!A24 -> 75389 | AB5: =東大阪!A25 -> 71794 | AC5: =東大阪!A26 -> 61099 | AD5: =東大阪!A27 -> 69710 | AE5: =東大阪!A28 -> 62766 | AF5: =東大阪!A29 -> 75397 | AG5: =東大阪!A30 -> 66974 | AH5: =東大阪!A31 -> 76194 | AI5: =東大阪!A32 -> 76408 | AJ5: =東大阪!A33 -> 71896 | AK5: =東大阪!A34 -> 67225 | AL5: =SUM(G5:AK5) -> 2217491 | AM5: =東大阪!F35 -> 3214
A6: =RANK(C6,$C$3:$C$44,0) -> 35 | B6: =RANK(E6,$E$3:$E$44,0) -> 33 | C6: =IF(E6<1,0,E6/D6) -> 0.7754675 | D6: =SUM(G67:AK67) -> 3292726 | E6: =SUM(G6:AK6) -> 2553402 | F6: 橿原 | G6: =橿原!A4 -> 90485 | H6: =橿原!A5 -> 77168 | I6: =橿原!A6 -> 77389 | J6: =橿原!A7 -> 74675 | K6: =橿原!A8 -> 79094 | L6: =橿原!A9 -> 87750 | M6: =橿原!A10 -> 79819 | N6: =橿原!A11 -> 92478 | O6: =橿原!A12 -> 72374 | P6: =橿原!A13 -> 76731 | Q6: =橿原!A14 -> 96005 | R6: =橿原!A15 -> 82954 | S6: =橿原!A16 -> 75980 | T6: =橿原!A17 -> 85198 | U6: =橿原!A18 -> 85536 | V6: =橿原!A19 -> 71086 | W6: =橿原!A20 -> 67806 | X6: =橿原!A21 -> 92804 | Y6: =橿原!A22 -> 72771 | Z6: =橿原!A23 -> 85379 | AA6: =橿原!A24 -> 90290 | AB6: =橿原!A25 -> 87210 | AC6: =橿原!A26 -> 76229 | AD6: =橿原!A27 -> 61720 | AE6: =橿原!A28 -> 90442 | AF6: =橿原!A29 -> 95985 | AG6: =橿原!A30 -> 90495 | AH6: =橿原!A31 -> 80717 | AI6: =橿原!A32 -> 88845 | AJ6: =橿原!A33 -> 89831 | AK6: =橿原!A34 -> 78156 | AL6: =SUM(G6:AK6) -> 2553402 | AM6: =橿原!F35 -> 3257
A7: =RANK(C7,$C$3:$C$44,0) -> 13 | B7: =RANK(E7,$E$3:$E$44,0) -> 13 | C7: =IF(E7<1,0,E7/D7) -> 1.011316 | D7: =SUM(G68:AK68) -> 5854628 | E7: =SUM(G7:AK7) -> 5920879 | F7: 京都 | G7: =京都!A4 -> 193485 | H7: =京都!A5 -> 189640 | I7: =京都!A6 -> 173050 | J7: =京都!A7 -> 179005 | K7: =京都!A8 -> 208080 | L7: =京都!A9 -> 170490 | M7: =京都!A10 -> 185290 | N7: =京都!A11 -> 175500 | O7: =京都!A12 -> 188864 | P7: =京都!A13 -> 191670 | Q7: =京都!A14 -> 210535 | R7: =京都!A15 -> 198575 | S7: =京都!A16 -> 186200 | T7: =京都!A17 -> 183180 | U7: =京都!A18 -> 193300 | V7: =京都!A19 -> 201930 | W7: =京都!A20 -> 212910 | X7: =京都!A21 -> 182550 | Y7: =京都!A22 -> 198190 | Z7: =京都!A23 -> 225750 | AA7: =京都!A24 -> 208620 | AB7: =京都!A25 -> 200315 | AC7: =京都!A26 -> 209965 | AD7: =京都!A27 -> 192570 | AE7: =京都!A28 -> 177835 | AF7: =京都!A29 -> 163390 | AG7: =京都!A30 -> 188530 | AH7: =京都!A31 -> 201380 | AI7: =京都!A32 -> 184260 | AJ7: =京都!A33 -> 192460 | AK7: =京都!A34 -> 153360 | AL7: =SUM(G7:AK7) -> 5920879 | AM7: =京都!F35 -> 6315
A8: =RANK(C8,$C$3:$C$44,0) -> 36 | B8: =RANK(E8,$E$3:$E$44,0) -> 37 | C8: =IF(E8<1,0,E8/D8) -> 0.73553804 | D8: =SUM(G69:AK69) -> 1642879 | E8: =SUM(G8:AK8) -> 1208400 | F8: 洛西 | G8: =洛西!A4 -> 46739 | H8: =洛西!A5 -> 38332 | I8: =洛西!A6 -> 30537 | J8: =洛西!A7 -> 38649 | K8: =洛西!A8 -> 36013 | L8: =洛西!A9 -> 38577 | M8: =洛西!A10 -> 40101 | N8: =洛西!A11 -> 42514 | O8: =洛西!A12 -> 37717 | P8: =洛西!A13 -> 33758 | Q8: =洛西!A14 -> 38750 | R8: =洛西!A15 -> 36011 | S8: =洛西!A16 -> 40215 | T8: =洛西!A17 -> 43019 | U8: =洛西!A18 -> 34056 | V8: =洛西!A19 -> 40856 | W8: =洛西!A20 -> 38333 | X8: =洛西!A21 -> 42959 | Y8: =洛西!A22 -> 39686 | Z8: =洛西!A23 -> 34420 | AA8: =洛西!A24 -> 37979 | AB8: =洛西!A25 -> 40228 | AC8: =洛西!A26 -> 38821 | AD8: =洛西!A27 -> 43306 | AE8: =洛西!A28 -> 31555 | AF8: =洛西!A29 -> 43491 | AG8: =洛西!A30 -> 41392 | AH8: =洛西!A31 -> 43012 | AI8: =洛西!A32 -> 41939 | AJ8: =洛西!A33 -> 41833 | AK8: =洛西!A34 -> 33602 | AL8: =SUM(G8:AK8) -> 1208400 | AM8: =洛西!F35 -> 1777
A9: =RANK(C9,$C$3:$C$44,0) -> 9 | B9: =RANK(E9,$E$3:$E$44,0) -> 27 | C9: =IF(E9<1,0,E9/D9) -> 1.035485 | D9: =SUM(G70:AK70) -> 3418708 | E9: =SUM(G9:AK9) -> 3540021 | F9: 和歌山 | G9: =和歌山!A4 -> 130462 | H9: =和歌山!A5 -> 94184 | I9: =和歌山!A6 -> 90546 | J9: =和歌山!A7 -> 113488 | K9: =和歌山!A8 -> 113290 | L9: =和歌山!A9 -> 114623 | M9: =和歌山!A10 -> 140606 | N9: =和歌山!A11 -> 170271 | O9: =和歌山!A12 -> 98514 | P9: =和歌山!A13 -> 107347 | Q9: =和歌山!A14 -> 107915 | R9: =和歌山!A15 -> 112361 | S9: =和歌山!A16 -> 105303 | T9: =和歌山!A17 -> 132296 | U9: =和歌山!A18 -> 126264 | V9: =和歌山!A19 -> 94984 | W9: =和歌山!A20 -> 103390 | X9: =和歌山!A21 -> 102519 | Y9: =和歌山!A22 -> 100147 | Z9: =和歌山!A23 -> 124178 | AA9: =和歌山!A24 -> 109389 | AB9: =和歌山!A25 -> 135523 | AC9: =和歌山!A26 -> 88407 | AD9: =和歌山!A27 -> 97776 | AE9: =和歌山!A28 -> 178080 | AF9: =和歌山!A29 -> 100867 | AG9: =和歌山!A30 -> 110427 | AH9: =和歌山!A31 -> 122755 | AI9: =和歌山!A32 -> 132247 | AJ9: =和歌山!A33 -> 103829 | AK9: =和歌山!A34 -> 78033 | AL9: =SUM(G9:AK9) -> 3540021 | AM9: =和歌山!F35 -> 4652
A10: =RANK(C10,$C$3:$C$44,0) -> 7 | B10: =RANK(E10,$E$3:$E$44,0) -> 16 | C10: =IF(E10<1,0,E10/D10) -> 1.0590354 | D10: =SUM(G71:AK71) -> 4824904 | E10: =SUM(G10:AK10) -> 5109744 | F10: 守口 | G10: =守口!A4 -> 169250 | H10: =守口!A5 -> 138663 | I10: =守口!A6 -> 214281 | J10: =守口!A7 -> 139318 | K10: =守口!A8 -> 164564 | L10: =守口!A9 -> 159049 | M10: =守口!A10 -> 165787 | N10: =守口!A11 -> 153242 | O10: =守口!A12 -> 124172 | P10: =守口!A13 -> 237449 | Q10: =守口!A14 -> 146159 | R10: =守口!A15 -> 154447 | S10: =守口!A16 -> 154712 | T10: =守口!A17 -> 163935 | U10: =守口!A18 -> 146883 | V10: =守口!A19 -> 150166 | W10: =守口!A20 -> 237185 | X10: =守口!A21 -> 116690 | Y10: =守口!A22 -> 152688 | Z10: =守口!A23 -> 159334 | AA10: =守口!A24 -> 168183 | AB10: =守口!A25 -> 184882 | AC10: =守口!A26 -> 124012 | AD10: =守口!A27 -> 253838 | AE10: =守口!A28 -> 138981 | AF10: =守口!A29 -> 160286 | AG10: =守口!A30 -> 150605 | AH10: =守口!A31 -> 162425 | AI10: =守口!A32 -> 165942 | AJ10: =守口!A33 -> 136131 | AK10: =守口!A34 -> 216485 | AL10: =SUM(G10:AK10) -> 5109744 | AM10: =守口!F35 -> 3695
A11: =RANK(C11,$C$3:$C$44,0) -> 23 | B11: =RANK(E11,$E$3:$E$44,0) -> 30 | C11: =IF(E11<1,0,E11/D11) -> 0.95077112 | D11: =SUM(G72:AK72) -> 3401987 | E11: =SUM(G11:AK11) -> 3234511 | F11: 枚方 | G11: =枚方!A4 -> 81592 | H11: =枚方!A5 -> 109314 | I11: =枚方!A6 -> 126596 | J11: =枚方!A7 -> 105178 | K11: =枚方!A8 -> 124886 | L11: =枚方!A9 -> 103968 | M11: =枚方!A10 -> 98686 | N11: =枚方!A11 -> 90462 | O11: =枚方!A12 -> 108152 | P11: =枚方!A13 -> 140970 | Q11: =枚方!A14 -> 111800 | R11: =枚方!A15 -> 101126 | S11: =枚方!A16 -> 114292 | T11: =枚方!A17 -> 94374 | U11: =枚方!A18 -> 77344 | V11: =枚方!A19 -> 104494 | W11: =枚方!A20 -> 146538 | X11: =枚方!A21 -> 103410 | Y11: =枚方!A22 -> 89186 | Z11: =枚方!A23 -> 76382 | AA11: =枚方!A24 -> 100150 | AB11: =枚方!A25 -> 89224 | AC11: =枚方!A26 -> 97203 | AD11: =枚方!A27 -> 145664 | AE11: =枚方!A28 -> 82036 | AF11: =枚方!A29 -> 98540 | AG11: =枚方!A30 -> 120950 | AH11: =枚方!A31 -> 90280 | AI11: =枚方!A32 -> 74148 | AJ11: =枚方!A33 -> 109660 | AK11: =枚方!A34 -> 117906 | AL11: =SUM(G11:AK11) -> 3234511 | AM11: =枚方!F35 -> 4366
A12: =RANK(C12,$C$3:$C$44,0) -> 19 | B12: =RANK(E12,$E$3:$E$44,0) -> 3 | C12: =IF(E12<1,0,E12/D12) -> 0.97459849 | D12: =SUM(G73:AK73) -> 11260157 | E12: =SUM(G12:AK12) -> 10974132 | F12: なんば | G12: =なんば!A4 -> 420533 | H12: =なんば!A5 -> 308884 | I12: =なんば!A6 -> 300294 | J12: =なんば!A7 -> 311193 | K12: =なんば!A8 -> 338704 | L12: =なんば!A9 -> 337715 | M12: =なんば!A10 -> 432469 | N12: =なんば!A11 -> 393425 | O12: =なんば!A12 -> 321430 | P12: =なんば!A13 -> 345928 | Q12: =なんば!A14 -> 357960 | R12: =なんば!A15 -> 340854 | S12: =なんば!A16 -> 342406 | T12: =なんば!A17 -> 394468 | U12: =なんば!A18 -> 367778 | V12: =なんば!A19 -> 330119 | W12: =なんば!A20 -> 326630 | X12: =なんば!A21 -> 330981 | Y12: =なんば!A22 -> 345023 | Z12: =なんば!A23 -> 425793 | AA12: =なんば!A24 -> 418839 | AB12: =なんば!A25 -> 365919 | AC12: =なんば!A26 -> 289758 | AD12: =なんば!A27 -> 309654 | AE12: =なんば!A28 -> 321235 | AF12: =なんば!A29 -> 353632 | AG12: =なんば!A30 -> 360439 | AH12: =なんば!A31 -> 424654 | AI12: =なんば!A32 -> 429044 | AJ12: =なんば!A33 -> 330011 | AK12: =なんば!A34 -> 298360 | AL12: =SUM(G12:AK12) -> 10974132 | AM12: =なんば!F35 -> 11502
A13: =RANK(C13,$C$3:$C$44,0) -> 38 | B13: =RANK(E13,$E$3:$E$44,0) -> 38 | C13: =IF(E13<1,0,E13/D13) -> 0 | D13: =SUM(G74:AK74) -> 4632618 | E13: =SUM(G13:AK13) -> 0 | F13: 堺 | G13: =堺!A4 -> 0 | H13: =堺!A5 -> 0 | I13: =堺!A6 -> 0 | J13: =堺!A7 -> 0 | K13: =堺!A8 -> 0 | L13: =堺!A9 -> 0 | M13: =堺!A10 -> 0 | N13: =堺!A11 -> 0 | O13: =堺!A12 -> 0 | P13: =堺!A13 -> 0 | Q13: =堺!A14 -> 0 | R13: =堺!A15 -> 0 | S13: =堺!A16 -> 0 | T13: =堺!A17 -> 0 | U13: =堺!A18 -> 0 | V13: =堺!A19 -> 0 | W13: =堺!A20 -> 0 | X13: =堺!A21 -> 0 | Y13: =堺!A22 -> 0 | Z13: =堺!A23 -> 0 | AA13: =堺!A24 -> 0 | AB13: =堺!A25 -> 0 | AC13: =堺!A26 -> 0 | AD13: =堺!A27 -> 0 | AE13: =堺!A28 -> 0 | AF13: =堺!A29 -> 0 | AG13: =堺!A30 -> 0 | AH13: =堺!A31 -> 0 | AI13: =堺!A32 -> 0 | AJ13: =堺!A33 -> 0 | AK13: =堺!A34 -> 0 | AL13: =SUM(G13:AK13) -> 0 | AM13: =堺!F35 -> 0
A14: =RANK(C14,$C$3:$C$44,0) -> 5 | B14: =RANK(E14,$E$3:$E$44,0) -> 2 | C14: =IF(E14<1,0,E14/D14) -> 1.0718437 | D14: =SUM(G75:AK75) -> 10866553 | E14: =SUM(G14:AK14) -> 11647246 | F14: 泉北 | G14: =泉北!A4 -> 407639 | H14: =泉北!A5 -> 333663 | I14: =泉北!A6 -> 330200 | J14: =泉北!A7 -> 340463 | K14: =泉北!A8 -> 355880 | L14: =泉北!A9 -> 335987 | M14: =泉北!A10 -> 372151 | N14: =泉北!A11 -> 390125 | O14: =泉北!A12 -> 344494 | P14: =泉北!A13 -> 331886 | Q14: =泉北!A14 -> 357670 | R14: =泉北!A15 -> 369429 | S14: =泉北!A16 -> 346341 | T14: =泉北!A17 -> 413801 | U14: =泉北!A18 -> 379065 | V14: =泉北!A19 -> 333923 | W14: =泉北!A20 -> 371647 | X14: =泉北!A21 -> 372560 | Y14: =泉北!A22 -> 386780 | Z14: =泉北!A23 -> 428098 | AA14: =泉北!A24 -> 422684 | AB14: =泉北!A25 -> 386860 | AC14: =泉北!A26 -> 350600 | AD14: =泉北!A27 -> 373533 | AE14: =泉北!A28 -> 386470 | AF14: =泉北!A29 -> 377039 | AG14: =泉北!A30 -> 400543 | AH14: =泉北!A31 -> 433078 | AI14: =泉北!A32 -> 483335 | AJ14: =泉北!A33 -> 375161 | AK14: =泉北!A34 -> 356141 | AL14: =SUM(G14:AK14) -> 11647246 | AM14: =泉北!F35 -> 19547
A15: =RANK(C15,$C$3:$C$44,0) -> 17 | B15: =RANK(E15,$E$3:$E$44,0) -> 22 | C15: =IF(E15<1,0,E15/D15) -> 0.97824008 | D15: =SUM(G76:AK76) -> 4668031 | E15: =SUM(G15:AK15) -> 4566455 | F15: 岡山 | G15: =岡山!A4 -> 181345 | H15: =岡山!A5 -> 135489 | I15: =岡山!A6 -> 133532 | J15: =岡山!A7 -> 151150 | K15: =岡山!A8 -> 136140 | L15: =岡山!A9 -> 120209 | M15: =岡山!A10 -> 162435 | N15: =岡山!A11 -> 143908 | O15: =岡山!A12 -> 124240 | P15: =岡山!A13 -> 137791 | Q15: =岡山!A14 -> 133995 | R15: =岡山!A15 -> 140940 | S15: =岡山!A16 -> 143071 | T15: =岡山!A17 -> 182001 | U15: =岡山!A18 -> 163631 | V15: =岡山!A19 -> 138598 | W15: =岡山!A20 -> 132713 | X15: =岡山!A21 -> 116982 | Y15: =岡山!A22 -> 175367 | Z15: =岡山!A23 -> 176665 | AA15: =岡山!A24 -> 159412 | AB15: =岡山!A25 -> 155367 | AC15: =岡山!A26 -> 134201 | AD15: =岡山!A27 -> 150760 | AE15: =岡山!A28 -> 135347 | AF15: =岡山!A29 -> 141113 | AG15: =岡山!A30 -> 148998 | AH15: =岡山!A31 -> 154287 | AI15: =岡山!A32 -> 171682 | AJ15: =岡山!A33 -> 146795 | AK15: =岡山!A34 -> 138291 | AL15: =SUM(G15:AK15) -> 4566455 | AM15: =岡山!F35 -> 4719
A16: =RANK(C16,$C$3:$C$44,0) -> 15 | B16: =RANK(E16,$E$3:$E$44,0) -> 6 | C16: =IF(E16<1,0,E16/D16) -> 0.99848969 | D16: =SUM(G77:AK77) -> 9809268 | E16: =SUM(G16:AK16) -> 9794453 | F16: うめ阪 | G16: =うめ阪!A4 -> 303210 | H16: =うめ阪!A5 -> 295575 | I16: =うめ阪!A6 -> 274894 | J16: =うめ阪!A7 -> 331898 | K16: =うめ阪!A8 -> 337394 | L16: =うめ阪!A9 -> 321592 | M16: =うめ阪!A10 -> 327802 | N16: =うめ阪!A11 -> 308450 | O16: =うめ阪!A12 -> 322983 | P16: =うめ阪!A13 -> 314843 | Q16: =うめ阪!A14 -> 339098 | R16: =うめ阪!A15 -> 327908 | S16: =うめ阪!A16 -> 343773 | T16: =うめ阪!A17 -> 289716 | U16: =うめ阪!A18 -> 304840 | V16: =うめ阪!A19 -> 312740 | W16: =うめ阪!A20 -> 334761 | X16: =うめ阪!A21 -> 306662 | Y16: =うめ阪!A22 -> 315096 | Z16: =うめ阪!A23 -> 333685 | AA16: =うめ阪!A24 -> 317304 | AB16: =うめ阪!A25 -> 303830 | AC16: =うめ阪!A26 -> 294919 | AD16: =うめ阪!A27 -> 328777 | AE16: =うめ阪!A28 -> 312972 | AF16: =うめ阪!A29 -> 314991 | AG16: =うめ阪!A30 -> 320544 | AH16: =うめ阪!A31 -> 319916 | AI16: =うめ阪!A32 -> 290426 | AJ16: =うめ阪!A33 -> 329965 | AK16: =うめ阪!A34 -> 313889 | AL16: =SUM(G16:AK16) -> 9794453 | AM16: =うめ阪!F35 -> 8613
A17: =RANK(C17,$C$3:$C$44,0) -> 25 | B17: =RANK(E17,$E$3:$E$44,0) -> 15 | C17: =IF(E17<1,0,E17/D17) -> 0.94455235 | D17: =SUM(G78:AK78) -> 5538053 | E17: =SUM(G17:AK17) -> 5230981 | F17: 宝塚 | G17: =宝塚!A4 -> 154615 | H17: =宝塚!A5 -> 155570 | I17: =宝塚!A6 -> 147080 | J17: =宝塚!A7 -> 191100 | K17: =宝塚!A8 -> 170270 | L17: =宝塚!A9 -> 180235 | M17: =宝塚!A10 -> 168315 | N17: =宝塚!A11 -> 175146 | O17: =宝塚!A12 -> 137650 | P17: =宝塚!A13 -> 167815 | Q17: =宝塚!A14 -> 174070 | R17: =宝塚!A15 -> 216325 | S17: =宝塚!A16 -> 160670 | T17: =宝塚!A17 -> 157290 | U17: =宝塚!A18 -> 139743 | V17: =宝塚!A19 -> 145573 | W17: =宝塚!A20 -> 191530 | X17: =宝塚!A21 -> 206171 | Y17: =宝塚!A22 -> 184360 | Z17: =宝塚!A23 -> 166280 | AA17: =宝塚!A24 -> 157915 | AB17: =宝塚!A25 -> 163930 | AC17: =宝塚!A26 -> 150375 | AD17: =宝塚!A27 -> 180870 | AE17: =宝塚!A28 -> 166988 | AF17: =宝塚!A29 -> 196185 | AG17: =宝塚!A30 -> 180615 | AH17: =宝塚!A31 -> 187215 | AI17: =宝塚!A32 -> 183940 | AJ17: =宝塚!A33 -> 142515 | AK17: =宝塚!A34 -> 130625 | AL17: =SUM(G17:AK17) -> 5230981 | AM17: =宝塚!F35 -> 5432
A18: =RANK(C18,$C$3:$C$44,0) -> 27 | B18: =RANK(E18,$E$3:$E$44,0) -> 11 | C18: =IF(E18<1,0,E18/D18) -> 0.92296832 | D18: =SUM(G79:AK79) -> 7787354 | E18: =SUM(G18:AK18) -> 7187481 | F18: 神戸阪 | G18: =神戸阪!A4 -> 213465 | H18: =神戸阪!A5 -> 237585 | I18: =神戸阪!A6 -> 195830 | J18: =神戸阪!A7 -> 240985 | K18: =神戸阪!A8 -> 231990 | L18: =神戸阪!A9 -> 232690 | M18: =神戸阪!A10 -> 240680 | N18: =神戸阪!A11 -> 247870 | O18: =神戸阪!A12 -> 224815 | P18: =神戸阪!A13 -> 235290 | Q18: =神戸阪!A14 -> 233100 | R18: =神戸阪!A15 -> 215525 | S18: =神戸阪!A16 -> 233235 | T18: =神戸阪!A17 -> 251015 | U18: =神戸阪!A18 -> 215585 | V18: =神戸阪!A19 -> 219715 | W18: =神戸阪!A20 -> 237115 | X18: =神戸阪!A21 -> 236950 | Y18: =神戸阪!A22 -> 221305 | Z18: =神戸阪!A23 -> 220435 | AA18: =神戸阪!A24 -> 244305 | AB18: =神戸阪!A25 -> 238425 | AC18: =神戸阪!A26 -> 207135 | AD18: =神戸阪!A27 -> 239956 | AE18: =神戸阪!A28 -> 248315 | AF18: =神戸阪!A29 -> 234605 | AG18: =神戸阪!A30 -> 234955 | AH18: =神戸阪!A31 -> 260930 | AI18: =神戸阪!A32 -> 268055 | AJ18: =神戸阪!A33 -> 222570 | AK18: =神戸阪!A34 -> 203050 | AL18: =SUM(G18:AK18) -> 7187481 | AM18: =神戸阪!F35 -> 7141
A19: =RANK(C19,$C$3:$C$44,0) -> 26 | B19: =RANK(E19,$E$3:$E$44,0) -> 23 | C19: =IF(E19<1,0,E19/D19) -> 0.92671345 | D19: =SUM(G80:AK80) -> 4619838 | E19: =SUM(G19:AK19) -> 4281266 | F19: 千里 | G19: =千里!A4 -> 140120 | H19: =千里!A5 -> 138208 | I19: =千里!A6 -> 133801 | J19: =千里!A7 -> 142389 | K19: =千里!A8 -> 137655 | L19: =千里!A9 -> 136040 | M19: =千里!A10 -> 133670 | N19: =千里!A11 -> 136789 | O19: =千里!A12 -> 138140 | P19: =千里!A13 -> 133980 | Q19: =千里!A14 -> 140670 | R19: =千里!A15 -> 151500 | S19: =千里!A16 -> 141040 | T19: =千里!A17 -> 138740 | U19: =千里!A18 -> 154659 | V19: =千里!A19 -> 156300 | W19: =千里!A20 -> 146230 | X19: =千里!A21 -> 138200 | Y19: =千里!A22 -> 133929 | Z19: =千里!A23 -> 137680 | AA19: =千里!A24 -> 133375 | AB19: =千里!A25 -> 139820 | AC19: =千里!A26 -> 130460 | AD19: =千里!A27 -> 141110 | AE19: =千里!A28 -> 154425 | AF19: =千里!A29 -> 132790 | AG19: =千里!A30 -> 117650 | AH19: =千里!A31 -> 137996 | AI19: =千里!A32 -> 128000 | AJ19: =千里!A33 -> 138485 | AK19: =千里!A34 -> 117415 | AL19: =SUM(G19:AK19) -> 4281266 | AM19: =千里!F35 -> 4387
A20: =RANK(C20,$C$3:$C$44,0) -> 34 | B20: =RANK(E20,$E$3:$E$44,0) -> 19 | C20: =IF(E20<1,0,E20/D20) -> 0.84074826 | D20: =SUM(G81:AK81) -> 5619405 | E20: =SUM(G20:AK20) -> 4724505 | F20: 京橋 | G20: =京橋!A4 -> 124070 | H20: =京橋!A5 -> 143130 | I20: =京橋!A6 -> 193520 | J20: =京橋!A7 -> 141940 | K20: =京橋!A8 -> 137780 | L20: =京橋!A9 -> 135790 | M20: =京橋!A10 -> 136840 | N20: =京橋!A11 -> 136520 | O20: =京橋!A12 -> 123900 | P20: =京橋!A13 -> 199690 | Q20: =京橋!A14 -> 143460 | R20: =京橋!A15 -> 154290 | S20: =京橋!A16 -> 134910 | T20: =京橋!A17 -> 141230 | U20: =京橋!A18 -> 117860 | V20: =京橋!A19 -> 139970 | W20: =京橋!A20 -> 204990 | X20: =京橋!A21 -> 136110 | Y20: =京橋!A22 -> 148470 | Z20: =京橋!A23 -> 152660 | AA20: =京橋!A24 -> 145100 | AB20: =京橋!A25 -> 146450 | AC20: =京橋!A26 -> 141840 | AD20: =京橋!A27 -> 205490 | AE20: =京橋!A28 -> 156527 | AF20: =京橋!A29 -> 155318 | AG20: =京橋!A30 -> 146220 | AH20: =京橋!A31 -> 157886 | AI20: =京橋!A32 -> 157686 | AJ20: =京橋!A33 -> 170880 | AK20: =京橋!A34 -> 193978 | AL20: =SUM(G20:AK20) -> 4724505 | AM20: =京橋!F35 -> 5507
A21: =RANK(C21,$C$3:$C$44,0) -> 12 | B21: =RANK(E21,$E$3:$E$44,0) -> 18 | C21: =IF(E21<1,0,E21/D21) -> 1.0278242 | D21: =SUM(G82:AK82) -> 4803368 | E21: =SUM(G21:AK21) -> 4937018 | F21: 川西 | G21: =川西!A4 -> 184670 | H21: =川西!A5 -> 158445 | I21: =川西!A6 -> 134158 | J21: =川西!A7 -> 158360 | K21: =川西!A8 -> 166221 | L21: =川西!A9 -> 167713 | M21: =川西!A10 -> 174750 | N21: =川西!A11 -> 157664 | O21: =川西!A12 -> 149486 | P21: =川西!A13 -> 173620 | Q21: =川西!A14 -> 151690 | R21: =川西!A15 -> 168855 | S21: =川西!A16 -> 156138 | T21: =川西!A17 -> 152785 | U21: =川西!A18 -> 159485 | V21: =川西!A19 -> 152569 | W21: =川西!A20 -> 163664 | X21: =川西!A21 -> 142044 | Y21: =川西!A22 -> 160188 | Z21: =川西!A23 -> 162185 | AA21: =川西!A24 -> 147510 | AB21: =川西!A25 -> 164495 | AC21: =川西!A26 -> 155911 | AD21: =川西!A27 -> 160721 | AE21: =川西!A28 -> 163738 | AF21: =川西!A29 -> 164315 | AG21: =川西!A30 -> 164713 | AH21: =川西!A31 -> 160779 | AI21: =川西!A32 -> 157915 | AJ21: =川西!A33 -> 160956 | AK21: =川西!A34 -> 141275 | AL21: =SUM(G21:AK21) -> 4937018 | AM21: =川西!F35 -> 5132
A22: =RANK(C22,$C$3:$C$44,0) -> 2 | B22: =RANK(E22,$E$3:$E$44,0) -> 1 | C22: =IF(E22<1,0,E22/D22) -> 1.1965483 | D22: =SUM(G83:AK83) -> 9780171 | E22: =SUM(G22:AK22) -> 11702447 | F22: 名古屋 | G22: =名古屋!A4 -> 409328 | H22: =名古屋!A5 -> 338949 | I22: =名古屋!A6 -> 335007 | J22: =名古屋!A7 -> 373589 | K22: =名古屋!A8 -> 383940 | L22: =名古屋!A9 -> 410198 | M22: =名古屋!A10 -> 382858 | N22: =名古屋!A11 -> 389641 | O22: =名古屋!A12 -> 367462 | P22: =名古屋!A13 -> 381277 | Q22: =名古屋!A14 -> 376516 | R22: =名古屋!A15 -> 382826 | S22: =名古屋!A16 -> 378475 | T22: =名古屋!A17 -> 406951 | U22: =名古屋!A18 -> 400058 | V22: =名古屋!A19 -> 377756 | W22: =名古屋!A20 -> 367104 | X22: =名古屋!A21 -> 369783 | Y22: =名古屋!A22 -> 426228 | Z22: =名古屋!A23 -> 391405 | AA22: =名古屋!A24 -> 366301 | AB22: =名古屋!A25 -> 381828 | AC22: =名古屋!A26 -> 356597 | AD22: =名古屋!A27 -> 398523 | AE22: =名古屋!A28 -> 360447 | AF22: =名古屋!A29 -> 368857 | AG22: =名古屋!A30 -> 391688 | AH22: =名古屋!A31 -> 364411 | AI22: =名古屋!A32 -> 392411 | AJ22: =名古屋!A33 -> 341691 | AK22: =名古屋!A34 -> 330342 | AL22: =SUM(G22:AK22) -> 11702447 | AM22: =名古屋!F35 -> 9245
A23: =RANK(C23,$C$3:$C$44,0) -> 38 | B23: =RANK(E23,$E$3:$E$44,0) -> 38 | C23: =IF(E23<1,0,E23/D23) -> 0 | D23: =SUM(G84:AK84) -> 2967324 | E23: =SUM(G23:AK23) -> 0 | F23: くずは | G23: =くずは!A4 -> 0 | H23: =くずは!A5 -> 0 | I23: =くずは!A6 -> 0 | J23: =くずは!A7 -> 0 | K23: =くずは!A8 -> 0 | L23: =くずは!A9 -> 0 | M23: =くずは!A10 -> 0 | N23: =くずは!A11 -> 0 | O23: =くずは!A12 -> 0 | P23: =くずは!A13 -> 0 | Q23: =くずは!A14 -> 0 | R23: =くずは!A15 -> 0 | S23: =くずは!A16 -> 0 | T23: =くずは!A17 -> 0 | U23: =くずは!A18 -> 0 | V23: =くずは!A19 -> 0 | W23: =くずは!A20 -> 0 | X23: =くずは!A21 -> 0 | Y23: =くずは!A22 -> 0 | Z23: =くずは!A23 -> 0 | AA23: =くずは!A24 -> 0 | AB23: =くずは!A25 -> 0 | AC23: =くずは!A26 -> 0 | AD23: =くずは!A27 -> 0 | AE23: =くずは!A28 -> 0 | AF23: =くずは!A29 -> 0 | AG23: =くずは!A30 -> 0 | AH23: =くずは!A31 -> 0 | AI23: =くずは!A32 -> 0 | AJ23: =くずは!A33 -> 0 | AK23: =くずは!A34 -> 0 | AL23: =SUM(G23:AK23) -> 0 | AM23: =くずは!F35 -> 0
A24: =RANK(C24,$C$3:$C$44,0) -> 38 | B24: =RANK(E24,$E$3:$E$44,0) -> 38 | C24: =IF(E24<1,0,E24/D24) -> 0 | D24: =SUM(G85:AK85) -> 2833646 | E24: =SUM(G24:AK24) -> 0 | F24: 須磨 | G24: =須磨!A4 -> 0 | H24: =須磨!A5 -> 0 | I24: =須磨!A6 -> 0 | J24: =須磨!A7 -> 0 | K24: =須磨!A8 -> 0 | L24: =須磨!A9 -> 0 | M24: =須磨!A10 -> 0 | N24: =須磨!A11 -> 0 | O24: =須磨!A12 -> 0 | P24: =須磨!A13 -> 0 | Q24: =須磨!A14 -> 0 | R24: =須磨!A15 -> 0 | S24: =須磨!A16 -> 0 | T24: =須磨!A17 -> 0 | U24: =須磨!A18 -> 0 | V24: =須磨!A19 -> 0 | W24: =須磨!A20 -> 0 | X24: =須磨!A21 -> 0 | Y24: =須磨!A22 -> 0 | Z24: =須磨!A23 -> 0 | AA24: =須磨!A24 -> 0 | AB24: =須磨!A25 -> 0 | AC24: =須磨!A26 -> 0 | AD24: =須磨!A27 -> 0 | AE24: =須磨!A28 -> 0 | AF24: =須磨!A29 -> 0 | AG24: =須磨!A30 -> 0 | AH24: =須磨!A31 -> 0 | AI24: =須磨!A32 -> 0 | AJ24: =須磨!A33 -> 0 | AK24: =須磨!A34 -> 0 | AL24: =SUM(G24:AK24) -> 0 | AM24: =須磨!F35 -> 0
A25: =RANK(C25,$C$3:$C$44,0) -> 24 | B25: =RANK(E25,$E$3:$E$44,0) -> 28 | C25: =IF(E25<1,0,E25/D25) -> 0.94712037 | D25: =SUM(G86:AK86) -> 3595335 | E25: =SUM(G25:AK25) -> 3405215 | F25: 小倉 | G25: =小倉!A4 -> 135360 | H25: =小倉!A5 -> 101230 | I25: =小倉!A6 -> 97160 | J25: =小倉!A7 -> 111390 | K25: =小倉!A8 -> 123120 | L25: =小倉!A9 -> 106380 | M25: =小倉!A10 -> 123490 | N25: =小倉!A11 -> 124020 | O25: =小倉!A12 -> 98260 | P25: =小倉!A13 -> 102050 | Q25: =小倉!A14 -> 117920 | R25: =小倉!A15 -> 107040 | S25: =小倉!A16 -> 110630 | T25: =小倉!A17 -> 117385 | U25: =小倉!A18 -> 134630 | V25: =小倉!A19 -> 100040 | W25: =小倉!A20 -> 105580 | X25: =小倉!A21 -> 114460 | Y25: =小倉!A22 -> 107840 | Z25: =小倉!A23 -> 127030 | AA25: =小倉!A24 -> 111270 | AB25: =小倉!A25 -> 111640 | AC25: =小倉!A26 -> 90650 | AD25: =小倉!A27 -> 90500 | AE25: =小倉!A28 -> 93470 | AF25: =小倉!A29 -> 113540 | AG25: =小倉!A30 -> 100030 | AH25: =小倉!A31 -> 122990 | AI25: =小倉!A32 -> 134570 | AJ25: =小倉!A33 -> 82660 | AK25: =小倉!A34 -> 88880 | AL25: =SUM(G25:AK25) -> 3405215 | AM25: =小倉!F35 -> 3426
A26: =RANK(C26,$C$3:$C$44,0) -> 6 | B26: =RANK(E26,$E$3:$E$44,0) -> 26 | C26: =IF(E26<1,0,E26/D26) -> 1.0631473 | D26: =SUM(G87:AK87) -> 3569416 | E26: =SUM(G26:AK26) -> 3794815 | F26: 流山 | G26: =流山!A4 -> 124543 | H26: =流山!A5 -> 114701 | I26: =流山!A6 -> 112345 | J26: =流山!A7 -> 124163 | K26: =流山!A8 -> 122697 | L26: =流山!A9 -> 127959 | M26: =流山!A10 -> 127741 | N26: =流山!A11 -> 129424 | O26: =流山!A12 -> 120812 | P26: =流山!A13 -> 114620 | Q26: =流山!A14 -> 124977 | R26: =流山!A15 -> 116063 | S26: =流山!A16 -> 124540 | T26: =流山!A17 -> 136989 | U26: =流山!A18 -> 139217 | V26: =流山!A19 -> 111703 | W26: =流山!A20 -> 114839 | X26: =流山!A21 -> 123749 | Y26: =流山!A22 -> 114304 | Z26: =流山!A23 -> 122103 | AA26: =流山!A24 -> 137739 | AB26: =流山!A25 -> 118567 | AC26: =流山!A26 -> 109650 | AD26: =流山!A27 -> 124860 | AE26: =流山!A28 -> 134533 | AF26: =流山!A29 -> 124460 | AG26: =流山!A30 -> 123983 | AH26: =流山!A31 -> 121611 | AI26: =流山!A32 -> 113221 | AJ26: =流山!A33 -> 130202 | AK26: =流山!A34 -> 108500 | AL26: =SUM(G26:AK26) -> 3794815 | AM26: =流山!F35 -> 0
A27: =RANK(C27,$C$3:$C$44,0) -> 1 | B27: =RANK(E27,$E$3:$E$44,0) -> 24 | C27: =IF(E27<1,0,E27/D27) -> 1.2649396 | D27: =SUM(G88:AK88) -> 3308324 | E27: =SUM(G27:AK27) -> 4184830 | F27: 新宿 | G27: =新宿!A4 -> 159699 | H27: =新宿!A5 -> 107459 | I27: =新宿!A6 -> 111142 | J27: =新宿!A7 -> 120106 | K27: =新宿!A8 -> 134624 | L27: =新宿!A9 -> 130164 | M27: =新宿!A10 -> 144840 | N27: =新宿!A11 -> 160624 | O27: =新宿!A12 -> 134095 | P27: =新宿!A13 -> 135557 | Q27: =新宿!A14 -> 136983 | R27: =新宿!A15 -> 129118 | S27: =新宿!A16 -> 127109 | T27: =新宿!A17 -> 161945 | U27: =新宿!A18 -> 157825 | V27: =新宿!A19 -> 121197 | W27: =新宿!A20 -> 132039 | X27: =新宿!A21 -> 132491 | Y27: =新宿!A22 -> 132712 | Z27: =新宿!A23 -> 153355 | AA27: =新宿!A24 -> 156889 | AB27: =新宿!A25 -> 168770 | AC27: =新宿!A26 -> 120649 | AD27: =新宿!A27 -> 136893 | AE27: =新宿!A28 -> 110469 | AF27: =新宿!A29 -> 110766 | AG27: =新宿!A30 -> 126624 | AH27: =新宿!A31 -> 152564 | AI27: =新宿!A32 -> 143435 | AJ27: =新宿!A33 -> 122183 | AK27: =新宿!A34 -> 112504 | AL27: =SUM(G27:AK27) -> 4184830 | AM27: =新宿!F35 -> 6277
A28: =RANK(C28,$C$3:$C$44,0) -> 38 | B28: =RANK(E28,$E$3:$E$44,0) -> 38 | C28: =IF(E28<1,0,E28/D28) -> 0 | D28: =SUM(G89:AK89) -> 2982300 | E28: =SUM(G28:AK28) -> 0 | F28: 川崎 | G28: =川崎!A4 -> 0 | H28: =川崎!A5 -> 0 | I28: =川崎!A6 -> 0 | J28: =川崎!A7 -> 0 | K28: =川崎!A8 -> 0 | L28: =川崎!A9 -> 0 | M28: =川崎!A10 -> 0 | N28: =川崎!A11 -> 0 | O28: =川崎!A12 -> 0 | P28: =川崎!A13 -> 0 | Q28: =川崎!A14 -> 0 | R28: =川崎!A15 -> 0 | S28: =川崎!A16 -> 0 | T28: =川崎!A17 -> 0 | U28: =川崎!A18 -> 0 | V28: =川崎!A19 -> 0 | W28: =川崎!A20 -> 0 | X28: =川崎!A21 -> 0 | Y28: =川崎!A22 -> 0 | Z28: =川崎!A23 -> 0 | AA28: =川崎!A24 -> 0 | AB28: =川崎!A25 -> 0 | AC28: =川崎!A26 -> 0 | AD28: =川崎!A27 -> 0 | AE28: =川崎!A28 -> 0 | AF28: =川崎!A29 -> 0 | AG28: =川崎!A30 -> 0 | AH28: =川崎!A31 -> 0 | AI28: =川崎!A32 -> 0 | AJ28: =川崎!A33 -> 0 | AK28: =川崎!A34 -> 0 | AL28: =SUM(G28:AK28) -> 0 | AM28: =川崎!F35 -> 0
A29: =RANK(C29,$C$3:$C$44,0) -> 8 | B29: =RANK(E29,$E$3:$E$44,0) -> 32 | C29: =IF(E29<1,0,E29/D29) -> 1.0506585 | D29: =SUM(G90:AK90) -> 2930310 | E29: =SUM(G29:AK29) -> 3078755 | F29: 松山 | G29: =松山!A4 -> 113557 | H29: =松山!A5 -> 99434 | I29: =松山!A6 -> 89756 | J29: =松山!A7 -> 96035 | K29: =松山!A8 -> 97591 | L29: =松山!A9 -> 93428 | M29: =松山!A10 -> 102947 | N29: =松山!A11 -> 115996 | O29: =松山!A12 -> 88721 | P29: =松山!A13 -> 89282 | Q29: =松山!A14 -> 108319 | R29: =松山!A15 -> 104736 | S29: =松山!A16 -> 101187 | T29: =松山!A17 -> 108146 | U29: =松山!A18 -> 96029 | V29: =松山!A19 -> 97176 | W29: =松山!A20 -> 100475 | X29: =松山!A21 -> 99376 | Y29: =松山!A22 -> 97759 | Z29: =松山!A23 -> 104155 | AA29: =松山!A24 -> 115240 | AB29: =松山!A25 -> 107568 | AC29: =松山!A26 -> 92898 | AD29: =松山!A27 -> 87494 | AE29: =松山!A28 -> 86649 | AF29: =松山!A29 -> 92686 | AG29: =松山!A30 -> 98477 | AH29: =松山!A31 -> 106580 | AI29: =松山!A32 -> 116510 | AJ29: =松山!A33 -> 83976 | AK29: =松山!A34 -> 86572 | AL29: =SUM(G29:AK29) -> 3078755 | AM29: =松山!F35 -> 3640
A30: =RANK(C30,$C$3:$C$44,0) -> 18 | B30: =RANK(E30,$E$3:$E$44,0) -> 5 | C30: =IF(E30<1,0,E30/D30) -> 0.97668346 | D30: =SUM(G91:AK91) -> 10267776 | E30: =SUM(G30:AK30) -> 10028367 | F30: 東京 | G30: =東京!A4 -> 288413 | H30: =東京!A5 -> 268736 | I30: =東京!A6 -> 271476 | J30: =東京!A7 -> 255163 | K30: =東京!A8 -> 306058 | L30: =東京!A9 -> 354402 | M30: =東京!A10 -> 316419 | N30: =東京!A11 -> 353189 | O30: =東京!A12 -> 297818 | P30: =東京!A13 -> 320026 | Q30: =東京!A14 -> 315592 | R30: =東京!A15 -> 347945 | S30: =東京!A16 -> 298396 | T30: =東京!A17 -> 305082 | U30: =東京!A18 -> 327426 | V30: =東京!A19 -> 289683 | W30: =東京!A20 -> 323528 | X30: =東京!A21 -> 304244 | Y30: =東京!A22 -> 367383 | Z30: =東京!A23 -> 398224 | AA30: =東京!A24 -> 307612 | AB30: =東京!A25 -> 363353 | AC30: =東京!A26 -> 308574 | AD30: =東京!A27 -> 325276 | AE30: =東京!A28 -> 308927 | AF30: =東京!A29 -> 341101 | AG30: =東京!A30 -> 377814 | AH30: =東京!A31 -> 366305 | AI30: =東京!A32 -> 370150 | AJ30: =東京!A33 -> 335580 | AK30: =東京!A34 -> 314472 | AL30: =SUM(G30:AK30) -> 10028367 | AM30: =東京!F35 -> 7686
A31: =RANK(C31,$C$3:$C$44,0) -> 37 | B31: =RANK(E31,$E$3:$E$44,0) -> 12 | C31: =IF(E31<1,0,E31/D31) -> 0.65444584 | D31: =SUM(G92:AK92) -> 9858822 | E31: =SUM(G31:AK31) -> 6452065 | F31: 池東武 | G31: =池東武!A4 -> 197350 | H31: =池東武!A5 -> 218508 | I31: =池東武!A6 -> 169376 | J31: =池東武!A7 -> 207438 | K31: =池東武!A8 -> 204930 | L31: =池東武!A9 -> 244121 | M31: =池東武!A10 -> 232127 | N31: =池東武!A11 -> 234216 | O31: =池東武!A12 -> 208628 | P31: =池東武!A13 -> 188113 | Q31: =池東武!A14 -> 203760 | R31: =池東武!A15 -> 219448 | S31: =池東武!A16 -> 241168 | T31: =池東武!A17 -> 218724 | U31: =池東武!A18 -> 191520 | V31: =池東武!A19 -> 197912 | W31: =池東武!A20 -> 223010 | X31: =池東武!A21 -> 202894 | Y31: =池東武!A22 -> 198121 | Z31: =池東武!A23 -> 247218 | AA31: =池東武!A24 -> 251246 | AB31: =池東武!A25 -> 200940 | AC31: =池東武!A26 -> 155706 | AD31: =池東武!A27 -> 197297 | AE31: =池東武!A28 -> 209322 | AF31: =池東武!A29 -> 172840 | AG31: =池東武!A30 -> 246525 | AH31: =池東武!A31 -> 205077 | AI31: =池東武!A32 -> 206895 | AJ31: =池東武!A33 -> 184860 | AK31: =池東武!A34 -> 172775 | AL31: =SUM(G31:AK31) -> 6452065 | AM31: =池東武!F35 -> 6391
A32: =RANK(C32,$C$3:$C$44,0) -> 11 | B32: =RANK(E32,$E$3:$E$44,0) -> 10 | C32: =IF(E32<1,0,E32/D32) -> 1.0289615 | D32: =SUM(G93:AK93) -> 7018121 | E32: =SUM(G32:AK32) -> 7221376 | F32: 西宮 | G32: =西宮!A4 -> 243313 | H32: =西宮!A5 -> 200483 | I32: =西宮!A6 -> 188490 | J32: =西宮!A7 -> 214500 | K32: =西宮!A8 -> 299724 | L32: =西宮!A9 -> 226487 | M32: =西宮!A10 -> 251279 | N32: =西宮!A11 -> 262318 | O32: =西宮!A12 -> 213175 | P32: =西宮!A13 -> 219270 | Q32: =西宮!A14 -> 220628 | R32: =西宮!A15 -> 224057 | S32: =西宮!A16 -> 248066 | T32: =西宮!A17 -> 255894 | U32: =西宮!A18 -> 248931 | V32: =西宮!A19 -> 211714 | W32: =西宮!A20 -> 236837 | X32: =西宮!A21 -> 210829 | Y32: =西宮!A22 -> 245384 | Z32: =西宮!A23 -> 243455 | AA32: =西宮!A24 -> 275219 | AB32: =西宮!A25 -> 236325 | AC32: =西宮!A26 -> 216741 | AD32: =西宮!A27 -> 235176 | AE32: =西宮!A28 -> 252023 | AF32: =西宮!A29 -> 231318 | AG32: =西宮!A30 -> 248578 | AH32: =西宮!A31 -> 216943 | AI32: =西宮!A32 -> 227169 | AJ32: =西宮!A33 -> 203135 | AK32: =西宮!A34 -> 213915 | AL32: =SUM(G32:AK32) -> 7221376 | AM32: =西宮!F35 -> 6673
A33: =RANK(C33,$C$3:$C$44,0) -> 10 | B33: =RANK(E33,$E$3:$E$44,0) -> 9 | C33: =IF(E33<1,0,E33/D33) -> 1.0339358 | D33: =SUM(G94:AK94) -> 8074824 | E33: =SUM(G33:AK33) -> 8348850 | F33: 横浜 | G33: =横浜!A4 -> 289881 | H33: =横浜!A5 -> 236689 | I33: =横浜!A6 -> 207081 | J33: =横浜!A7 -> 257714 | K33: =横浜!A8 -> 315982 | L33: =横浜!A9 -> 304366 | M33: =横浜!A10 -> 276340 | N33: =横浜!A11 -> 270048 | O33: =横浜!A12 -> 272310 | P33: =横浜!A13 -> 269508 | Q33: =横浜!A14 -> 285348 | R33: =横浜!A15 -> 265964 | S33: =横浜!A16 -> 304127 | T33: =横浜!A17 -> 283882 | U33: =横浜!A18 -> 270019 | V33: =横浜!A19 -> 256100 | W33: =横浜!A20 -> 266897 | X33: =横浜!A21 -> 261507 | Y33: =横浜!A22 -> 279273 | Z33: =横浜!A23 -> 310611 | AA33: =横浜!A24 -> 291635 | AB33: =横浜!A25 -> 229269 | AC33: =横浜!A26 -> 270376 | AD33: =横浜!A27 -> 240261 | AE33: =横浜!A28 -> 244168 | AF33: =横浜!A29 -> 233364 | AG33: =横浜!A30 -> 298177 | AH33: =横浜!A31 -> 284373 | AI33: =横浜!A32 -> 241858 | AJ33: =横浜!A33 -> 276633 | AK33: =横浜!A34 -> 255089 | AL33: =SUM(G33:AK33) -> 8348850 | AM33: =横浜!F35 -> 6630
A34: =RANK(C34,$C$3:$C$44,0) -> 28 | B34: =RANK(E34,$E$3:$E$44,0) -> 34 | C34: =IF(E34<1,0,E34/D34) -> 0.91276749 | D34: =SUM(G95:AK95) -> 2788089 | E34: =SUM(G34:AK34) -> 2544877 | F34: あまがさき | G34: =あまが!A4 -> 104727 | H34: =あまが!A5 -> 74382 | I34: =あまが!A6 -> 70319 | J34: =あまが!A7 -> 78124 | K34: =あまが!A8 -> 80757 | L34: =あまが!A9 -> 73240 | M34: =あまが!A10 -> 98647 | N34: =あまが!A11 -> 113055 | O34: =あまが!A12 -> 74995 | P34: =あまが!A13 -> 73230 | Q34: =あまが!A14 -> 71351 | R34: =あまが!A15 -> 67386 | S34: =あまが!A16 -> 71696 | T34: =あまが!A17 -> 98307 | U34: =あまが!A18 -> 108755 | V34: =あまが!A19 -> 68838 | W34: =あまが!A20 -> 74780 | X34: =あまが!A21 -> 71583 | Y34: =あまが!A22 -> 66040 | Z34: =あまが!A23 -> 104009 | AA34: =あまが!A24 -> 89096 | AB34: =あまが!A25 -> 90249 | AC34: =あまが!A26 -> 70975 | AD34: =あまが!A27 -> 74657 | AE34: =あまが!A28 -> 62382 | AF34: =あまが!A29 -> 83447 | AG34: =あまが!A30 -> 80695 | AH34: =あまが!A31 -> 96807 | AI34: =あまが!A32 -> 109156 | AJ34: =あまが!A33 -> 75013 | AK34: =あまが!A34 -> 68179 | AL34: =SUM(G34:AK34) -> 2544877 | AM34: =あまが!F35 -> 3614
A35: =RANK(C35,$C$3:$C$44,0) -> 14 | B35: =RANK(E35,$E$3:$E$44,0) -> 29 | C35: =IF(E35<1,0,E35/D35) -> 1.0074452 | D35: =SUM(G96:AK96) -> 3345630 | E35: =SUM(G35:AK35) -> 3370539 | F35: 梅大丸 | G35: =梅大丸!A4 -> 105945 | H35: =梅大丸!A5 -> 90811 | I35: =梅大丸!A6 -> 98076 | J35: =梅大丸!A7 -> 101310 | K35: =梅大丸!A8 -> 107753 | L35: =梅大丸!A9 -> 111248 | M35: =梅大丸!A10 -> 129751 | N35: =梅大丸!A11 -> 124219 | O35: =梅大丸!A12 -> 96226 | P35: =梅大丸!A13 -> 98821 | Q35: =梅大丸!A14 -> 107077 | R35: =梅大丸!A15 -> 119644 | S35: =梅大丸!A16 -> 115811 | T35: =梅大丸!A17 -> 128361 | U35: =梅大丸!A18 -> 111187 | V35: =梅大丸!A19 -> 106894 | W35: =梅大丸!A20 -> 116257 | X35: =梅大丸!A21 -> 104147 | Y35: =梅大丸!A22 -> 110814 | Z35: =梅大丸!A23 -> 116269 | AA35: =梅大丸!A24 -> 134814 | AB35: =梅大丸!A25 -> 117377 | AC35: =梅大丸!A26 -> 90146 | AD35: =梅大丸!A27 -> 91507 | AE35: =梅大丸!A28 -> 97550 | AF35: =梅大丸!A29 -> 111509 | AG35: =梅大丸!A30 -> 113070 | AH35: =梅大丸!A31 -> 114726 | AI35: =梅大丸!A32 -> 112456 | AJ35: =梅大丸!A33 -> 89447 | AK35: =梅大丸!A34 -> 97316 | AL35: =SUM(G35:AK35) -> 3370539 | AM35: =梅大丸!F35 -> 3033
A36: =RANK(C36,$C$3:$C$44,0) -> 3 | B36: =RANK(E36,$E$3:$E$44,0) -> 25 | C36: =IF(E36<1,0,E36/D36) -> 1.1313925 | D36: =SUM(G97:AK97) -> 3478022 | E36: =SUM(G36:AK36) -> 3935008 | F36: 柏 | G36: =柏!A4 -> 110859 | H36: =柏!A5 -> 135632 | I36: =柏!A6 -> 118315 | J36: =柏!A7 -> 115748 | K36: =柏!A8 -> 150190 | L36: =柏!A9 -> 145936 | M36: =柏!A10 -> 121123 | N36: =柏!A11 -> 102070 | O36: =柏!A12 -> 135635 | P36: =柏!A13 -> 104594 | Q36: =柏!A14 -> 136475 | R36: =柏!A15 -> 123724 | S36: =柏!A16 -> 147738 | T36: =柏!A17 -> 134873 | U36: =柏!A18 -> 110920 | V36: =柏!A19 -> 116646 | W36: =柏!A20 -> 144800 | X36: =柏!A21 -> 145397 | Y36: =柏!A22 -> 123165 | Z36: =柏!A23 -> 116715 | AA36: =柏!A24 -> 111415 | AB36: =柏!A25 -> 130355 | AC36: =柏!A26 -> 120061 | AD36: =柏!A27 -> 138511 | AE36: =柏!A28 -> 145146 | AF36: =柏!A29 -> 111375 | AG36: =柏!A30 -> 145825 | AH36: =柏!A31 -> 111767 | AI36: =柏!A32 -> 128618 | AJ36: =柏!A33 -> 135145 | AK36: =柏!A34 -> 116235 | AL36: =SUM(G36:AK36) -> 3935008 | AM36: =柏!F35 -> 3886
A37: =RANK(C37,$C$3:$C$44,0) -> 21 | B37: =RANK(E37,$E$3:$E$44,0) -> 31 | C37: =IF(E37<1,0,E37/D37) -> 0.9550998 | D37: =SUM(G98:AK98) -> 3354172 | E37: =SUM(G37:AK37) -> 3203569 | F37: 神大丸 | G37: =神大丸!A4 -> 96690 | H37: =神大丸!A5 -> 99646 | I37: =神大丸!A6 -> 79335 | J37: =神大丸!A7 -> 99177 | K37: =神大丸!A8 -> 107521 | L37: =神大丸!A9 -> 93918 | M37: =神大丸!A10 -> 101482 | N37: =神大丸!A11 -> 100774 | O37: =神大丸!A12 -> 123188 | P37: =神大丸!A13 -> 101514 | Q37: =神大丸!A14 -> 106690 | R37: =神大丸!A15 -> 107909 | S37: =神大丸!A16 -> 105090 | T37: =神大丸!A17 -> 114005 | U37: =神大丸!A18 -> 105178 | V37: =神大丸!A19 -> 97324 | W37: =神大丸!A20 -> 104721 | X37: =神大丸!A21 -> 99902 | Y37: =神大丸!A22 -> 107658 | Z37: =神大丸!A23 -> 103606 | AA37: =神大丸!A24 -> 112665 | AB37: =神大丸!A25 -> 113629 | AC37: =神大丸!A26 -> 82299 | AD37: =神大丸!A27 -> 103365 | AE37: =神大丸!A28 -> 106111 | AF37: =神大丸!A29 -> 113029 | AG37: =神大丸!A30 -> 105634 | AH37: =神大丸!A31 -> 102588 | AI37: =神大丸!A32 -> 105074 | AJ37: =神大丸!A33 -> 99700 | AK37: =神大丸!A34 -> 104147 | AL37: =SUM(G37:AK37) -> 3203569 | AM37: =神大丸!F35 -> 3667
A38: =RANK(C38,$C$3:$C$44,0) -> 29 | B38: =RANK(E38,$E$3:$E$44,0) -> 20 | C38: =IF(E38<1,0,E38/D38) -> 0.91120073 | D38: =SUM(G99:AK99) -> 5103916 | E38: =SUM(G38:AK38) -> 4650692 | F38: 栄 | G38: =栄!A4 -> 154970 | H38: =栄!A5 -> 145090 | I38: =栄!A6 -> 129013 | J38: =栄!A7 -> 174651 | K38: =栄!A8 -> 184143 | L38: =栄!A9 -> 150246 | M38: =栄!A10 -> 140343 | N38: =栄!A11 -> 142495 | O38: =栄!A12 -> 150812 | P38: =栄!A13 -> 157459 | Q38: =栄!A14 -> 171317 | R38: =栄!A15 -> 158183 | S38: =栄!A16 -> 158845 | T38: =栄!A17 -> 142056 | U38: =栄!A18 -> 157699 | V38: =栄!A19 -> 139905 | W38: =栄!A20 -> 143918 | X38: =栄!A21 -> 147626 | Y38: =栄!A22 -> 130996 | Z38: =栄!A23 -> 152818 | AA38: =栄!A24 -> 165266 | AB38: =栄!A25 -> 156080 | AC38: =栄!A26 -> 142093 | AD38: =栄!A27 -> 168712 | AE38: =栄!A28 -> 132768 | AF38: =栄!A29 -> 142075 | AG38: =栄!A30 -> 153371 | AH38: =栄!A31 -> 159180 | AI38: =栄!A32 -> 165205 | AJ38: =栄!A33 -> 128621 | AK38: =栄!A34 -> 104736 | AL38: =SUM(G38:AK38) -> 4650692 | AM38: =栄!F35 -> 4050
A39: =RANK(C39,$C$3:$C$44,0) -> 4 | B39: =RANK(E39,$E$3:$E$44,0) -> 21 | C39: =IF(E39<1,0,E39/D39) -> 1.0741843 | D39: =SUM(G100:AK100) -> 4273477 | E39: =SUM(G39:AK39) -> 4590502 | F39: 上野 | G39: =上野!A4 -> 139056 | H39: =上野!A5 -> 136470 | I39: =上野!A6 -> 126349 | J39: =上野!A7 -> 117107 | K39: =上野!A8 -> 131896 | L39: =上野!A9 -> 144162 | M39: =上野!A10 -> 143282 | N39: =上野!A11 -> 146358 | O39: =上野!A12 -> 128842 | P39: =上野!A13 -> 128474 | Q39: =上野!A14 -> 158553 | R39: =上野!A15 -> 156166 | S39: =上野!A16 -> 166065 | T39: =上野!A17 -> 151897 | U39: =上野!A18 -> 132680 | V39: =上野!A19 -> 150960 | W39: =上野!A20 -> 148127 | X39: =上野!A21 -> 138947 | Y39: =上野!A22 -> 152448 | Z39: =上野!A23 -> 181807 | AA39: =上野!A24 -> 163723 | AB39: =上野!A25 -> 167315 | AC39: =上野!A26 -> 144999 | AD39: =上野!A27 -> 146687 | AE39: =上野!A28 -> 123023 | AF39: =上野!A29 -> 128246 | AG39: =上野!A30 -> 168744 | AH39: =上野!A31 -> 183647 | AI39: =上野!A32 -> 187134 | AJ39: =上野!A33 -> 172306 | AK39: =上野!A34 -> 125032 | AL39: =SUM(G39:AK39) -> 4590502 | AM39: =上野!F35 -> 4376
A40: =RANK(C40,$C$3:$C$44,0) -> 32 | B40: =RANK(E40,$E$3:$E$44,0) -> 17 | C40: =IF(E40<1,0,E40/D40) -> 0.87570262 | D40: =SUM(G101:AK101) -> 5681423 | E40: =SUM(G40:AK40) -> 4975237 | F40: はか阪 | G40: =はか阪!A4 -> 160615 | H40: =はか阪!A5 -> 130600 | I40: =はか阪!A6 -> 127573 | J40: =はか阪!A7 -> 163823 | K40: =はか阪!A8 -> 140463 | L40: =はか阪!A9 -> 141122 | M40: =はか阪!A10 -> 153947 | N40: =はか阪!A11 -> 169860 | O40: =はか阪!A12 -> 156164 | P40: =はか阪!A13 -> 166464 | Q40: =はか阪!A14 -> 203149 | R40: =はか阪!A15 -> 145909 | S40: =はか阪!A16 -> 175673 | T40: =はか阪!A17 -> 178237 | U40: =はか阪!A18 -> 187195 | V40: =はか阪!A19 -> 149535 | W40: =はか阪!A20 -> 142426 | X40: =はか阪!A21 -> 133741 | Y40: =はか阪!A22 -> 161355 | Z40: =はか阪!A23 -> 195895 | AA40: =はか阪!A24 -> 169715 | AB40: =はか阪!A25 -> 193344 | AC40: =はか阪!A26 -> 143395 | AD40: =はか阪!A27 -> 157368 | AE40: =はか阪!A28 -> 168916 | AF40: =はか阪!A29 -> 161160 | AG40: =はか阪!A30 -> 168785 | AH40: =はか阪!A31 -> 149965 | AI40: =はか阪!A32 -> 172044 | AJ40: =はか阪!A33 -> 157612 | AK40: =はか阪!A34 -> 149187 | AL40: =SUM(G40:AK40) -> 4975237 | AM40: =はか阪!F35 -> 5168
...

Sheet 時間別
C1: 12：00 | E1: 15：00 | G1: 17：00 | I1: からすかれい煮付
A3: 日付 | C3: 客数 | D3: 合計 | E3: 客数 | F3: 合計 | G3: 客数 | H3: 合計 | I3: 製造数量 | J3: 廃棄数量
A4: 46082 | B4: 日 | C4: =あべの!AA4+上本町!AA4+東大阪!AA4+橿原!AA4+京都!AA4+洛西!AA4+和歌山!AA4+守口!AA4+枚方!AA4+なんば!AA4+堺!AA4+泉北!AA4+岡山!AA4+うめ阪!AA4+宝塚!AA4+神戸阪!AA4+千里!AA4+京橋!AA4+川西!AA4+須磨!AA4+名古屋!AA4+小倉!AA4+くずは!AA4+流山!AA4+新宿!AA4+川崎!AA4+松山!AA4+東京!AA4+池東武!AA4+西宮!AA4+横浜!AA4+あまが!AA4+梅大丸!AA4+柏!AA4+神大丸!AA4+栄!AA4+上野!AA4+はか阪!AA4+高槻!AA4+梅阪神!AA4 -> 1154 | D4: =あべの!AB4+上本町!AB4+東大阪!AB4+橿原!AB4+京都!AB4+洛西!AB4+和歌山!AB4+守口!AB4+枚方!AB4+なんば!AB4+堺!AB4+泉北!AB4+岡山!AB4+うめ阪!AB4+宝塚!AB4+神戸阪!AB4+千里!AB4+京橋!AB4+川西!AB4+須磨!AB4+名古屋!AB4+小倉!AB4+くずは!AB4+流山!AB4+新宿!AB4+川崎!AB4+松山!AB4+東京!AB4+池東武!AB4+西宮!AB4+横浜!AB4+あまが!AB4+梅大丸!AB4+柏!AB4+神大丸!AB4+栄!AB4+上野!AB4+はか阪!AB4+高槻!AB4+梅阪神!AB4 -> 1309286 | E4: =あべの!AC4+上本町!AC4+東大阪!AC4+橿原!AC4+京都!AC4+洛西!AC4+和歌山!AC4+守口!AC4+枚方!AC4+なんば!AC4+堺!AC4+泉北!AC4+岡山!AC4+うめ阪!AC4+宝塚!AC4+神戸阪!AC4+千里!AC4+京橋!AC4+川西!AC4+須磨!AC4+名古屋!AC4+小倉!AC4+くずは!AC4+流山!AC4+新宿!AC4+川崎!AC4+松山!AC4+東京!AC4+池東武!AC4+西宮!AC4+横浜!AC4+あまが!AC4+梅大丸!AC4+柏!AC4+神大丸!AC4+栄!AC4+上野!AC4+はか阪!AC4+高槻!AC4+梅阪神!AC4 -> 2970 | F4: =あべの!AD4+上本町!AD4+東大阪!AD4+橿原!AD4+京都!AD4+洛西!AD4+和歌山!AD4+守口!AD4+枚方!AD4+なんば!AD4+堺!AD4+泉北!AD4+岡山!AD4+うめ阪!AD4+宝塚!AD4+神戸阪!AD4+千里!AD4+京橋!AD4+川西!AD4+須磨!AD4+名古屋!AD4+小倉!AD4+くずは!AD4+流山!AD4+新宿!AD4+川崎!AD4+松山!AD4+東京!AD4+池東武!AD4+西宮!AD4+横浜!AD4+あまが!AD4+梅大丸!AD4+柏!AD4+神大丸!AD4+栄!AD4+上野!AD4+はか阪!AD4+高槻!AD4+梅阪神!AD4 -> 3321853 | G4: =あべの!AE4+上本町!AE4+東大阪!AE4+橿原!AE4+京都!AE4+洛西!AE4+和歌山!AE4+守口!AE4+枚方!AE4+なんば!AE4+堺!AE4+泉北!AE4+岡山!AE4+うめ阪!AE4+宝塚!AE4+神戸阪!AE4+千里!AE4+京橋!AE4+川西!AE4+須磨!AE4+名古屋!AE4+小倉!AE4+くずは!AE4+流山!AE4+新宿!AE4+川崎!AE4+松山!AE4+東京!AE4+池東武!AE4+西宮!AE4+横浜!AE4+あまが!AE4+梅大丸!AE4+柏!AE4+神大丸!AE4+栄!AE4+上野!AE4+はか阪!AE4+高槻!AE4+梅阪神!AE4 -> 4090 | H4: =あべの!AF4+上本町!AF4+東大阪!AF4+橿原!AF4+京都!AF4+洛西!AF4+和歌山!AF4+守口!AF4+枚方!AF4+なんば!AF4+堺!AF4+泉北!AF4+岡山!AF4+うめ阪!AF4+宝塚!AF4+神戸阪!AF4+千里!AF4+京橋!AF4+川西!AF4+須磨!AF4+名古屋!AF4+小倉!AF4+くずは!AF4+流山!AF4+新宿!AF4+川崎!AF4+松山!AF4+東京!AF4+池東武!AF4+西宮!AF4+横浜!AF4+あまが!AF4+梅大丸!AF4+柏!AF4+神大丸!AF4+栄!AF4+上野!AF4+はか阪!AF4+高槻!AF4+梅阪神!AF4 -> 4581774 | I4: =あべの!AG4+上本町!AG4+東大阪!AG4+橿原!AG4+京都!AG4+洛西!AG4+和歌山!AG4+守口!AG4+枚方!AG4+なんば!AG4+堺!AG4+泉北!AG4+岡山!AG4+うめ阪!AG4+宝塚!AG4+神戸阪!AG4+千里!AG4+京橋!AG4+川西!AG4+須磨!AG4+名古屋!AG4+小倉!AG4+くずは!AG4+流山!AG4+新宿!AG4+川崎!AG4+松山!AG4+東京!AG4+池東武!AG4+西宮!AG4+横浜!AG4+あまが!AG4+梅大丸!AG4+柏!AG4+神大丸!AG4+栄!AG4+上野!AG4+はか阪!AG4+高槻!AG4+梅阪神!AG4 -> 593 | J4: =あべの!AH4+上本町!AH4+東大阪!AH4+橿原!AH4+京都!AH4+洛西!AH4+和歌山!AH4+守口!AH4+枚方!AH4+なんば!AH4+堺!AH4+泉北!AH4+岡山!AH4+うめ阪!AH4+宝塚!AH4+神戸阪!AH4+千里!AH4+京橋!AH4+川西!AH4+須磨!AH4+名古屋!AH4+小倉!AH4+くずは!AH4+流山!AH4+新宿!AH4+川崎!AH4+松山!AH4+東京!AH4+池東武!AH4+西宮!AH4+横浜!AH4+あまが!AH4+梅大丸!AH4+柏!AH4+神大丸!AH4+栄!AH4+上野!AH4+はか阪!AH4+高槻!AH4+梅阪神!AH4 -> 13
A5: 46083 | B5: 月 | C5: =あべの!AA5+上本町!AA5+東大阪!AA5+橿原!AA5+京都!AA5+洛西!AA5+和歌山!AA5+守口!AA5+枚方!AA5+なんば!AA5+堺!AA5+泉北!AA5+岡山!AA5+うめ阪!AA5+宝塚!AA5+神戸阪!AA5+千里!AA5+京橋!AA5+川西!AA5+須磨!AA5+名古屋!AA5+小倉!AA5+くずは!AA5+流山!AA5+新宿!AA5+川崎!AA5+松山!AA5+東京!AA5+池東武!AA5+西宮!AA5+横浜!AA5+あまが!AA5+梅大丸!AA5+柏!AA5+神大丸!AA5+栄!AA5+上野!AA5+はか阪!AA5+高槻!AA5+梅阪神!AA5 -> 1055 | D5: =あべの!AB5+上本町!AB5+東大阪!AB5+橿原!AB5+京都!AB5+洛西!AB5+和歌山!AB5+守口!AB5+枚方!AB5+なんば!AB5+堺!AB5+泉北!AB5+岡山!AB5+うめ阪!AB5+宝塚!AB5+神戸阪!AB5+千里!AB5+京橋!AB5+川西!AB5+須磨!AB5+名古屋!AB5+小倉!AB5+くずは!AB5+流山!AB5+新宿!AB5+川崎!AB5+松山!AB5+東京!AB5+池東武!AB5+西宮!AB5+横浜!AB5+あまが!AB5+梅大丸!AB5+柏!AB5+神大丸!AB5+栄!AB5+上野!AB5+はか阪!AB5+高槻!AB5+梅阪神!AB5 -> 1119583 | E5: =あべの!AC5+上本町!AC5+東大阪!AC5+橿原!AC5+京都!AC5+洛西!AC5+和歌山!AC5+守口!AC5+枚方!AC5+なんば!AC5+堺!AC5+泉北!AC5+岡山!AC5+うめ阪!AC5+宝塚!AC5+神戸阪!AC5+千里!AC5+京橋!AC5+川西!AC5+須磨!AC5+名古屋!AC5+小倉!AC5+くずは!AC5+流山!AC5+新宿!AC5+川崎!AC5+松山!AC5+東京!AC5+池東武!AC5+西宮!AC5+横浜!AC5+あまが!AC5+梅大丸!AC5+柏!AC5+神大丸!AC5+栄!AC5+上野!AC5+はか阪!AC5+高槻!AC5+梅阪神!AC5 -> 2816 | F5: =あべの!AD5+上本町!AD5+東大阪!AD5+橿原!AD5+京都!AD5+洛西!AD5+和歌山!AD5+守口!AD5+枚方!AD5+なんば!AD5+堺!AD5+泉北!AD5+岡山!AD5+うめ阪!AD5+宝塚!AD5+神戸阪!AD5+千里!AD5+京橋!AD5+川西!AD5+須磨!AD5+名古屋!AD5+小倉!AD5+くずは!AD5+流山!AD5+新宿!AD5+川崎!AD5+松山!AD5+東京!AD5+池東武!AD5+西宮!AD5+横浜!AD5+あまが!AD5+梅大丸!AD5+柏!AD5+神大丸!AD5+栄!AD5+上野!AD5+はか阪!AD5+高槻!AD5+梅阪神!AD5 -> 2998021 | G5: =あべの!AE5+上本町!AE5+東大阪!AE5+橿原!AE5+京都!AE5+洛西!AE5+和歌山!AE5+守口!AE5+枚方!AE5+なんば!AE5+堺!AE5+泉北!AE5+岡山!AE5+うめ阪!AE5+宝塚!AE5+神戸阪!AE5+千里!AE5+京橋!AE5+川西!AE5+須磨!AE5+名古屋!AE5+小倉!AE5+くずは!AE5+流山!AE5+新宿!AE5+川崎!AE5+松山!AE5+東京!AE5+池東武!AE5+西宮!AE5+横浜!AE5+あまが!AE5+梅大丸!AE5+柏!AE5+神大丸!AE5+栄!AE5+上野!AE5+はか阪!AE5+高槻!AE5+梅阪神!AE5 -> 4020 | H5: =あべの!AF5+上本町!AF5+東大阪!AF5+橿原!AF5+京都!AF5+洛西!AF5+和歌山!AF5+守口!AF5+枚方!AF5+なんば!AF5+堺!AF5+泉北!AF5+岡山!AF5+うめ阪!AF5+宝塚!AF5+神戸阪!AF5+千里!AF5+京橋!AF5+川西!AF5+須磨!AF5+名古屋!AF5+小倉!AF5+くずは!AF5+流山!AF5+新宿!AF5+川崎!AF5+松山!AF5+東京!AF5+池東武!AF5+西宮!AF5+横浜!AF5+あまが!AF5+梅大丸!AF5+柏!AF5+神大丸!AF5+栄!AF5+上野!AF5+はか阪!AF5+高槻!AF5+梅阪神!AF5 -> 4216633 | I5: =あべの!AG5+上本町!AG5+東大阪!AG5+橿原!AG5+京都!AG5+洛西!AG5+和歌山!AG5+守口!AG5+枚方!AG5+なんば!AG5+堺!AG5+泉北!AG5+岡山!AG5+うめ阪!AG5+宝塚!AG5+神戸阪!AG5+千里!AG5+京橋!AG5+川西!AG5+須磨!AG5+名古屋!AG5+小倉!AG5+くずは!AG5+流山!AG5+新宿!AG5+川崎!AG5+松山!AG5+東京!AG5+池東武!AG5+西宮!AG5+横浜!AG5+あまが!AG5+梅大丸!AG5+柏!AG5+神大丸!AG5+栄!AG5+上野!AG5+はか阪!AG5+高槻!AG5+梅阪神!AG5 -> 574 | J5: =あべの!AH5+上本町!AH5+東大阪!AH5+橿原!AH5+京都!AH5+洛西!AH5+和歌山!AH5+守口!AH5+枚方!AH5+なんば!AH5+堺!AH5+泉北!AH5+岡山!AH5+うめ阪!AH5+宝塚!AH5+神戸阪!AH5+千里!AH5+京橋!AH5+川西!AH5+須磨!AH5+名古屋!AH5+小倉!AH5+くずは!AH5+流山!AH5+新宿!AH5+川崎!AH5+松山!AH5+東京!AH5+池東武!AH5+西宮!AH5+横浜!AH5+あまが!AH5+梅大丸!AH5+柏!AH5+神大丸!AH5+栄!AH5+上野!AH5+はか阪!AH5+高槻!AH5+梅阪神!AH5 -> 21
A6: 46084 | B6: 火 | C6: =あべの!AA6+上本町!AA6+東大阪!AA6+橿原!AA6+京都!AA6+洛西!AA6+和歌山!AA6+守口!AA6+枚方!AA6+なんば!AA6+堺!AA6+泉北!AA6+岡山!AA6+うめ阪!AA6+宝塚!AA6+神戸阪!AA6+千里!AA6+京橋!AA6+川西!AA6+須磨!AA6+名古屋!AA6+小倉!AA6+くずは!AA6+流山!AA6+新宿!AA6+川崎!AA6+松山!AA6+東京!AA6+池東武!AA6+西宮!AA6+横浜!AA6+あまが!AA6+梅大丸!AA6+柏!AA6+神大丸!AA6+栄!AA6+上野!AA6+はか阪!AA6+高槻!AA6+梅阪神!AA6 -> 828 | D6: =あべの!AB6+上本町!AB6+東大阪!AB6+橿原!AB6+京都!AB6+洛西!AB6+和歌山!AB6+守口!AB6+枚方!AB6+なんば!AB6+堺!AB6+泉北!AB6+岡山!AB6+うめ阪!AB6+宝塚!AB6+神戸阪!AB6+千里!AB6+京橋!AB6+川西!AB6+須磨!AB6+名古屋!AB6+小倉!AB6+くずは!AB6+流山!AB6+新宿!AB6+川崎!AB6+松山!AB6+東京!AB6+池東武!AB6+西宮!AB6+横浜!AB6+あまが!AB6+梅大丸!AB6+柏!AB6+神大丸!AB6+栄!AB6+上野!AB6+はか阪!AB6+高槻!AB6+梅阪神!AB6 -> 901792 | E6: =あべの!AC6+上本町!AC6+東大阪!AC6+橿原!AC6+京都!AC6+洛西!AC6+和歌山!AC6+守口!AC6+枚方!AC6+なんば!AC6+堺!AC6+泉北!AC6+岡山!AC6+うめ阪!AC6+宝塚!AC6+神戸阪!AC6+千里!AC6+京橋!AC6+川西!AC6+須磨!AC6+名古屋!AC6+小倉!AC6+くずは!AC6+流山!AC6+新宿!AC6+川崎!AC6+松山!AC6+東京!AC6+池東武!AC6+西宮!AC6+横浜!AC6+あまが!AC6+梅大丸!AC6+柏!AC6+神大丸!AC6+栄!AC6+上野!AC6+はか阪!AC6+高槻!AC6+梅阪神!AC6 -> 2394 | F6: =あべの!AD6+上本町!AD6+東大阪!AD6+橿原!AD6+京都!AD6+洛西!AD6+和歌山!AD6+守口!AD6+枚方!AD6+なんば!AD6+堺!AD6+泉北!AD6+岡山!AD6+うめ阪!AD6+宝塚!AD6+神戸阪!AD6+千里!AD6+京橋!AD6+川西!AD6+須磨!AD6+名古屋!AD6+小倉!AD6+くずは!AD6+流山!AD6+新宿!AD6+川崎!AD6+松山!AD6+東京!AD6+池東武!AD6+西宮!AD6+横浜!AD6+あまが!AD6+梅大丸!AD6+柏!AD6+神大丸!AD6+栄!AD6+上野!AD6+はか阪!AD6+高槻!AD6+梅阪神!AD6 -> 2604890 | G6: =あべの!AE6+上本町!AE6+東大阪!AE6+橿原!AE6+京都!AE6+洛西!AE6+和歌山!AE6+守口!AE6+枚方!AE6+なんば!AE6+堺!AE6+泉北!AE6+岡山!AE6+うめ阪!AE6+宝塚!AE6+神戸阪!AE6+千里!AE6+京橋!AE6+川西!AE6+須磨!AE6+名古屋!AE6+小倉!AE6+くずは!AE6+流山!AE6+新宿!AE6+川崎!AE6+松山!AE6+東京!AE6+池東武!AE6+西宮!AE6+横浜!AE6+あまが!AE6+梅大丸!AE6+柏!AE6+神大丸!AE6+栄!AE6+上野!AE6+はか阪!AE6+高槻!AE6+梅阪神!AE6 -> 3516 | H6: =あべの!AF6+上本町!AF6+東大阪!AF6+橿原!AF6+京都!AF6+洛西!AF6+和歌山!AF6+守口!AF6+枚方!AF6+なんば!AF6+堺!AF6+泉北!AF6+岡山!AF6+うめ阪!AF6+宝塚!AF6+神戸阪!AF6+千里!AF6+京橋!AF6+川西!AF6+須磨!AF6+名古屋!AF6+小倉!AF6+くずは!AF6+流山!AF6+新宿!AF6+川崎!AF6+松山!AF6+東京!AF6+池東武!AF6+西宮!AF6+横浜!AF6+あまが!AF6+梅大丸!AF6+柏!AF6+神大丸!AF6+栄!AF6+上野!AF6+はか阪!AF6+高槻!AF6+梅阪神!AF6 -> 3739632 | I6: =あべの!AG6+上本町!AG6+東大阪!AG6+橿原!AG6+京都!AG6+洛西!AG6+和歌山!AG6+守口!AG6+枚方!AG6+なんば!AG6+堺!AG6+泉北!AG6+岡山!AG6+うめ阪!AG6+宝塚!AG6+神戸阪!AG6+千里!AG6+京橋!AG6+川西!AG6+須磨!AG6+名古屋!AG6+小倉!AG6+くずは!AG6+流山!AG6+新宿!AG6+川崎!AG6+松山!AG6+東京!AG6+池東武!AG6+西宮!AG6+横浜!AG6+あまが!AG6+梅大丸!AG6+柏!AG6+神大丸!AG6+栄!AG6+上野!AG6+はか阪!AG6+高槻!AG6+梅阪神!AG6 -> 559 | J6: =あべの!AH6+上本町!AH6+東大阪!AH6+橿原!AH6+京都!AH6+洛西!AH6+和歌山!AH6+守口!AH6+枚方!AH6+なんば!AH6+堺!AH6+泉北!AH6+岡山!AH6+うめ阪!AH6+宝塚!AH6+神戸阪!AH6+千里!AH6+京橋!AH6+川西!AH6+須磨!AH6+名古屋!AH6+小倉!AH6+くずは!AH6+流山!AH6+新宿!AH6+川崎!AH6+松山!AH6+東京!AH6+池東武!AH6+西宮!AH6+横浜!AH6+あまが!AH6+梅大丸!AH6+柏!AH6+神大丸!AH6+栄!AH6+上野!AH6+はか阪!AH6+高槻!AH6+梅阪神!AH6 -> 30
A7: 46085 | B7: 水 | C7: =あべの!AA7+上本町!AA7+東大阪!AA7+橿原!AA7+京都!AA7+洛西!AA7+和歌山!AA7+守口!AA7+枚方!AA7+なんば!AA7+堺!AA7+泉北!AA7+岡山!AA7+うめ阪!AA7+宝塚!AA7+神戸阪!AA7+千里!AA7+京橋!AA7+川西!AA7+須磨!AA7+名古屋!AA7+小倉!AA7+くずは!AA7+流山!AA7+新宿!AA7+川崎!AA7+松山!AA7+東京!AA7+池東武!AA7+西宮!AA7+横浜!AA7+あまが!AA7+梅大丸!AA7+柏!AA7+神大丸!AA7+栄!AA7+上野!AA7+はか阪!AA7+高槻!AA7+梅阪神!AA7 -> 992 | D7: =あべの!AB7+上本町!AB7+東大阪!AB7+橿原!AB7+京都!AB7+洛西!AB7+和歌山!AB7+守口!AB7+枚方!AB7+なんば!AB7+堺!AB7+泉北!AB7+岡山!AB7+うめ阪!AB7+宝塚!AB7+神戸阪!AB7+千里!AB7+京橋!AB7+川西!AB7+須磨!AB7+名古屋!AB7+小倉!AB7+くずは!AB7+流山!AB7+新宿!AB7+川崎!AB7+松山!AB7+東京!AB7+池東武!AB7+西宮!AB7+横浜!AB7+あまが!AB7+梅大丸!AB7+柏!AB7+神大丸!AB7+栄!AB7+上野!AB7+はか阪!AB7+高槻!AB7+梅阪神!AB7 -> 1093221 | E7: =あべの!AC7+上本町!AC7+東大阪!AC7+橿原!AC7+京都!AC7+洛西!AC7+和歌山!AC7+守口!AC7+枚方!AC7+なんば!AC7+堺!AC7+泉北!AC7+岡山!AC7+うめ阪!AC7+宝塚!AC7+神戸阪!AC7+千里!AC7+京橋!AC7+川西!AC7+須磨!AC7+名古屋!AC7+小倉!AC7+くずは!AC7+流山!AC7+新宿!AC7+川崎!AC7+松山!AC7+東京!AC7+池東武!AC7+西宮!AC7+横浜!AC7+あまが!AC7+梅大丸!AC7+柏!AC7+神大丸!AC7+栄!AC7+上野!AC7+はか阪!AC7+高槻!AC7+梅阪神!AC7 -> 2756 | F7: =あべの!AD7+上本町!AD7+東大阪!AD7+橿原!AD7+京都!AD7+洛西!AD7+和歌山!AD7+守口!AD7+枚方!AD7+なんば!AD7+堺!AD7+泉北!AD7+岡山!AD7+うめ阪!AD7+宝塚!AD7+神戸阪!AD7+千里!AD7+京橋!AD7+川西!AD7+須磨!AD7+名古屋!AD7+小倉!AD7+くずは!AD7+流山!AD7+新宿!AD7+川崎!AD7+松山!AD7+東京!AD7+池東武!AD7+西宮!AD7+横浜!AD7+あまが!AD7+梅大丸!AD7+柏!AD7+神大丸!AD7+栄!AD7+上野!AD7+はか阪!AD7+高槻!AD7+梅阪神!AD7 -> 3039723 | G7: =あべの!AE7+上本町!AE7+東大阪!AE7+橿原!AE7+京都!AE7+洛西!AE7+和歌山!AE7+守口!AE7+枚方!AE7+なんば!AE7+堺!AE7+泉北!AE7+岡山!AE7+うめ阪!AE7+宝塚!AE7+神戸阪!AE7+千里!AE7+京橋!AE7+川西!AE7+須磨!AE7+名古屋!AE7+小倉!AE7+くずは!AE7+流山!AE7+新宿!AE7+川崎!AE7+松山!AE7+東京!AE7+池東武!AE7+西宮!AE7+横浜!AE7+あまが!AE7+梅大丸!AE7+柏!AE7+神大丸!AE7+栄!AE7+上野!AE7+はか阪!AE7+高槻!AE7+梅阪神!AE7 -> 4084 | H7: =あべの!AF7+上本町!AF7+東大阪!AF7+橿原!AF7+京都!AF7+洛西!AF7+和歌山!AF7+守口!AF7+枚方!AF7+なんば!AF7+堺!AF7+泉北!AF7+岡山!AF7+うめ阪!AF7+宝塚!AF7+神戸阪!AF7+千里!AF7+京橋!AF7+川西!AF7+須磨!AF7+名古屋!AF7+小倉!AF7+くずは!AF7+流山!AF7+新宿!AF7+川崎!AF7+松山!AF7+東京!AF7+池東武!AF7+西宮!AF7+横浜!AF7+あまが!AF7+梅大丸!AF7+柏!AF7+神大丸!AF7+栄!AF7+上野!AF7+はか阪!AF7+高槻!AF7+梅阪神!AF7 -> 4372739 | I7: =あべの!AG7+上本町!AG7+東大阪!AG7+橿原!AG7+京都!AG7+洛西!AG7+和歌山!AG7+守口!AG7+枚方!AG7+なんば!AG7+堺!AG7+泉北!AG7+岡山!AG7+うめ阪!AG7+宝塚!AG7+神戸阪!AG7+千里!AG7+京橋!AG7+川西!AG7+須磨!AG7+名古屋!AG7+小倉!AG7+くずは!AG7+流山!AG7+新宿!AG7+川崎!AG7+松山!AG7+東京!AG7+池東武!AG7+西宮!AG7+横浜!AG7+あまが!AG7+梅大丸!AG7+柏!AG7+神大丸!AG7+栄!AG7+上野!AG7+はか阪!AG7+高槻!AG7+梅阪神!AG7 -> 627 | J7: =あべの!AH7+上本町!AH7+東大阪!AH7+橿原!AH7+京都!AH7+洛西!AH7+和歌山!AH7+守口!AH7+枚方!AH7+なんば!AH7+堺!AH7+泉北!AH7+岡山!AH7+うめ阪!AH7+宝塚!AH7+神戸阪!AH7+千里!AH7+京橋!AH7+川西!AH7+須磨!AH7+名古屋!AH7+小倉!AH7+くずは!AH7+流山!AH7+新宿!AH7+川崎!AH7+松山!AH7+東京!AH7+池東武!AH7+西宮!AH7+横浜!AH7+あまが!AH7+梅大丸!AH7+柏!AH7+神大丸!AH7+栄!AH7+上野!AH7+はか阪!AH7+高槻!AH7+梅阪神!AH7 -> 18
A8: 46086 | B8: 木 | C8: =あべの!AA8+上本町!AA8+東大阪!AA8+橿原!AA8+京都!AA8+洛西!AA8+和歌山!AA8+守口!AA8+枚方!AA8+なんば!AA8+堺!AA8+泉北!AA8+岡山!AA8+うめ阪!AA8+宝塚!AA8+神戸阪!AA8+千里!AA8+京橋!AA8+川西!AA8+須磨!AA8+名古屋!AA8+小倉!AA8+くずは!AA8+流山!AA8+新宿!AA8+川崎!AA8+松山!AA8+東京!AA8+池東武!AA8+西宮!AA8+横浜!AA8+あまが!AA8+梅大丸!AA8+柏!AA8+神大丸!AA8+栄!AA8+上野!AA8+はか阪!AA8+高槻!AA8+梅阪神!AA8 -> 1080 | D8: =あべの!AB8+上本町!AB8+東大阪!AB8+橿原!AB8+京都!AB8+洛西!AB8+和歌山!AB8+守口!AB8+枚方!AB8+なんば!AB8+堺!AB8+泉北!AB8+岡山!AB8+うめ阪!AB8+宝塚!AB8+神戸阪!AB8+千里!AB8+京橋!AB8+川西!AB8+須磨!AB8+名古屋!AB8+小倉!AB8+くずは!AB8+流山!AB8+新宿!AB8+川崎!AB8+松山!AB8+東京!AB8+池東武!AB8+西宮!AB8+横浜!AB8+あまが!AB8+梅大丸!AB8+柏!AB8+神大丸!AB8+栄!AB8+上野!AB8+はか阪!AB8+高槻!AB8+梅阪神!AB8 -> 1142816 | E8: =あべの!AC8+上本町!AC8+東大阪!AC8+橿原!AC8+京都!AC8+洛西!AC8+和歌山!AC8+守口!AC8+枚方!AC8+なんば!AC8+堺!AC8+泉北!AC8+岡山!AC8+うめ阪!AC8+宝塚!AC8+神戸阪!AC8+千里!AC8+京橋!AC8+川西!AC8+須磨!AC8+名古屋!AC8+小倉!AC8+くずは!AC8+流山!AC8+新宿!AC8+川崎!AC8+松山!AC8+東京!AC8+池東武!AC8+西宮!AC8+横浜!AC8+あまが!AC8+梅大丸!AC8+柏!AC8+神大丸!AC8+栄!AC8+上野!AC8+はか阪!AC8+高槻!AC8+梅阪神!AC8 -> 2972 | F8: =あべの!AD8+上本町!AD8+東大阪!AD8+橿原!AD8+京都!AD8+洛西!AD8+和歌山!AD8+守口!AD8+枚方!AD8+なんば!AD8+堺!AD8+泉北!AD8+岡山!AD8+うめ阪!AD8+宝塚!AD8+神戸阪!AD8+千里!AD8+京橋!AD8+川西!AD8+須磨!AD8+名古屋!AD8+小倉!AD8+くずは!AD8+流山!AD8+新宿!AD8+川崎!AD8+松山!AD8+東京!AD8+池東武!AD8+西宮!AD8+横浜!AD8+あまが!AD8+梅大丸!AD8+柏!AD8+神大丸!AD8+栄!AD8+上野!AD8+はか阪!AD8+高槻!AD8+梅阪神!AD8 -> 3249831 | G8: =あべの!AE8+上本町!AE8+東大阪!AE8+橿原!AE8+京都!AE8+洛西!AE8+和歌山!AE8+守口!AE8+枚方!AE8+なんば!AE8+堺!AE8+泉北!AE8+岡山!AE8+うめ阪!AE8+宝塚!AE8+神戸阪!AE8+千里!AE8+京橋!AE8+川西!AE8+須磨!AE8+名古屋!AE8+小倉!AE8+くずは!AE8+流山!AE8+新宿!AE8+川崎!AE8+松山!AE8+東京!AE8+池東武!AE8+西宮!AE8+横浜!AE8+あまが!AE8+梅大丸!AE8+柏!AE8+神大丸!AE8+栄!AE8+上野!AE8+はか阪!AE8+高槻!AE8+梅阪神!AE8 -> 4429 | H8: =あべの!AF8+上本町!AF8+東大阪!AF8+橿原!AF8+京都!AF8+洛西!AF8+和歌山!AF8+守口!AF8+枚方!AF8+なんば!AF8+堺!AF8+泉北!AF8+岡山!AF8+うめ阪!AF8+宝塚!AF8+神戸阪!AF8+千里!AF8+京橋!AF8+川西!AF8+須磨!AF8+名古屋!AF8+小倉!AF8+くずは!AF8+流山!AF8+新宿!AF8+川崎!AF8+松山!AF8+東京!AF8+池東武!AF8+西宮!AF8+横浜!AF8+あまが!AF8+梅大丸!AF8+柏!AF8+神大丸!AF8+栄!AF8+上野!AF8+はか阪!AF8+高槻!AF8+梅阪神!AF8 -> 4732109 | I8: =あべの!AG8+上本町!AG8+東大阪!AG8+橿原!AG8+京都!AG8+洛西!AG8+和歌山!AG8+守口!AG8+枚方!AG8+なんば!AG8+堺!AG8+泉北!AG8+岡山!AG8+うめ阪!AG8+宝塚!AG8+神戸阪!AG8+千里!AG8+京橋!AG8+川西!AG8+須磨!AG8+名古屋!AG8+小倉!AG8+くずは!AG8+流山!AG8+新宿!AG8+川崎!AG8+松山!AG8+東京!AG8+池東武!AG8+西宮!AG8+横浜!AG8+あまが!AG8+梅大丸!AG8+柏!AG8+神大丸!AG8+栄!AG8+上野!AG8+はか阪!AG8+高槻!AG8+梅阪神!AG8 -> 590 | J8: =あべの!AH8+上本町!AH8+東大阪!AH8+橿原!AH8+京都!AH8+洛西!AH8+和歌山!AH8+守口!AH8+枚方!AH8+なんば!AH8+堺!AH8+泉北!AH8+岡山!AH8+うめ阪!AH8+宝塚!AH8+神戸阪!AH8+千里!AH8+京橋!AH8+川西!AH8+須磨!AH8+名古屋!AH8+小倉!AH8+くずは!AH8+流山!AH8+新宿!AH8+川崎!AH8+松山!AH8+東京!AH8+池東武!AH8+西宮!AH8+横浜!AH8+あまが!AH8+梅大丸!AH8+柏!AH8+神大丸!AH8+栄!AH8+上野!AH8+はか阪!AH8+高槻!AH8+梅阪神!AH8 -> 2
